Workbook

Sheet Resource Model
A1: Resource Model
A2: All values are formulas — change source data and this sheet recalculates
A3: Refresh required: Capacity Heatmap, Gantt, weekly role heatmap, demand column, project duration estimates, suggested dates
A4: Time Allocation
A5: Base Hours/Week | B5: =RM_Assumptions!B6
A6: Admin % | B6: =RM_Assumptions!B7
A7: Support/Break-Fix % | B7: =RM_Assumptions!B8
A8: Project % | B8: =RM_Assumptions!B9
A9: Project Hrs/Person/Wk | B9: =RM_Assumptions!B10
A10: Max Projects/Person | B10: =RM_Assumptions!B12
A12: SDLC Phase Weights
A13: Phase | B13: Discovery | C13: Planning | D13: Design | E13: Build | F13: Test | G13: Deploy/Hypercare | H13: Total
A14: Weight | B14: =RM_Assumptions!B16 | C14: =RM_Assumptions!C16 | D14: =RM_Assumptions!D16 | E14: =RM_Assumptions!E16 | F14: =RM_Assumptions!F16 | G14: =RM_Assumptions!G16 | H14: =SUM(B14:G14)
A16: Role Effort by SDLC Phase
A17: Role | B17: Discovery | C17: Planning | D17: Design | E17: Build | F17: Test | G17: Deploy/Hypercare | H17: Total
A18: Project Manager | B18: =RM_Assumptions!B21 | C18: =RM_Assumptions!C21 | D18: =RM_Assumptions!D21 | E18: =RM_Assumptions!E21 | F18: =RM_Assumptions!F21 | G18: =RM_Assumptions!G21 | H18: =SUM(B18:G18)
A19: DBA | B19: =RM_Assumptions!B22 | C19: =RM_Assumptions!C22 | D19: =RM_Assumptions!D22 | E19: =RM_Assumptions!E22 | F19: =RM_Assumptions!F22 | G19: =RM_Assumptions!G22 | H19: =SUM(B19:G19)
A20: IT Business Analyst/SME | B20: =RM_Assumptions!B23 | C20: =RM_Assumptions!C23 | D20: =RM_Assumptions!D23 | E20: =RM_Assumptions!E23 | F20: =RM_Assumptions!F23 | G20: =RM_Assumptions!G23 | H20: =SUM(B20:G20)
A21: IT Functional Analyst | B21: =RM_Assumptions!B24 | C21: =RM_Assumptions!C24 | D21: =RM_Assumptions!D24 | E21: =RM_Assumptions!E24 | F21: =RM_Assumptions!F24 | G21: =RM_Assumptions!G24 | H21: =SUM(B21:G21)
A22: IT Tech Analyst/Developer | B22: =RM_Assumptions!B25 | C22: =RM_Assumptions!C25 | D22: =RM_Assumptions!D25 | E22: =RM_Assumptions!E25 | F22: =RM_Assumptions!F25 | G22: =RM_Assumptions!G25 | H22: =SUM(B22:G22)
A23: Developer | B23: =RM_Assumptions!B26 | C23: =RM_Assumptions!C26 | D23: =RM_Assumptions!D26 | E23: =RM_Assumptions!E26 | F23: =RM_Assumptions!F26 | G23: =RM_Assumptions!G26 | H23: =SUM(B23:G23)
A24: Infrastructure | B24: =RM_Assumptions!B27 | C24: =RM_Assumptions!C27 | D24: =RM_Assumptions!D27 | E24: =RM_Assumptions!E27 | F24: =RM_Assumptions!F27 | G24: =RM_Assumptions!G27 | H24: =SUM(B24:G24)
A25: WMS Consultant | B25: =RM_Assumptions!B28 | C25: =RM_Assumptions!C28 | D25: =RM_Assumptions!D28 | E25: =RM_Assumptions!E28 | F25: =RM_Assumptions!F28 | G25: =RM_Assumptions!G28 | H25: =SUM(B25:G25)
A27: Per-Person Capacity
A28: Role | B28: Headcount | C28: Team Supply (hrs/wk) | D28: Per-Person (hrs/wk)
A29: Project Manager | B29: =COUNTIF('Team Roster'!$B$4:$B$26,"Project Manager") | C29: =SUMIFS('Team Roster'!$K$4:$K$26,'Team Roster'!$B$4:$B$26,"Project Manager") | D29: =IFERROR(AVERAGEIFS('Team Roster'!$K$4:$K$26,'Team Roster'!$B$4:$B$26,"Project Manager"),0)
A30: DBA | B30: =COUNTIF('Team Roster'!$B$4:$B$26,"DBA") | C30: =SUMIFS('Team Roster'!$K$4:$K$26,'Team Roster'!$B$4:$B$26,"DBA") | D30: =IFERROR(AVERAGEIFS('Team Roster'!$K$4:$K$26,'Team Roster'!$B$4:$B$26,"DBA"),0)
A31: IT Business Analyst/SME | B31: =COUNTIF('Team Roster'!$B$4:$B$26,"Business Analyst") | C31: =SUMIFS('Team Roster'!$K$4:$K$26,'Team Roster'!$B$4:$B$26,"Business Analyst") | D31: =IFERROR(AVERAGEIFS('Team Roster'!$K$4:$K$26,'Team Roster'!$B$4:$B$26,"Business Analyst"),0)
A32: IT Functional Analyst | B32: =COUNTIF('Team Roster'!$B$4:$B$26,"Functional") | C32: =SUMIFS('Team Roster'!$K$4:$K$26,'Team Roster'!$B$4:$B$26,"Functional") | D32: =IFERROR(AVERAGEIFS('Team Roster'!$K$4:$K$26,'Team Roster'!$B$4:$B$26,"Functional"),0)
A33: IT Tech Analyst/Developer | B33: =COUNTIF('Team Roster'!$B$4:$B$26,"Technical") | C33: =SUMIFS('Team Roster'!$K$4:$K$26,'Team Roster'!$B$4:$B$26,"Technical") | D33: =IFERROR(AVERAGEIFS('Team Roster'!$K$4:$K$26,'Team Roster'!$B$4:$B$26,"Technical"),0)
A34: Developer | B34: =COUNTIF('Team Roster'!$B$4:$B$26,"Developer") | C34: =SUMIFS('Team Roster'!$K$4:$K$26,'Team Roster'!$B$4:$B$26,"Developer") | D34: =IFERROR(AVERAGEIFS('Team Roster'!$K$4:$K$26,'Team Roster'!$B$4:$B$26,"Developer"),0)
A35: Infrastructure | B35: =COUNTIF('Team Roster'!$B$4:$B$26,"Infrastructure") | C35: =SUMIFS('Team Roster'!$K$4:$K$26,'Team Roster'!$B$4:$B$26,"Infrastructure") | D35: =IFERROR(AVERAGEIFS('Team Roster'!$K$4:$K$26,'Team Roster'!$B$4:$B$26,"Infrastructure"),0)
A36: WMS Consultant | B36: =COUNTIF('Team Roster'!$B$4:$B$26,"WMS Consultant") | C36: =SUMIFS('Team Roster'!$K$4:$K$26,'Team Roster'!$B$4:$B$26,"WMS Consultant") | D36: =IFERROR(AVERAGEIFS('Team Roster'!$K$4:$K$26,'Team Roster'!$B$4:$B$26,"WMS Consultant"),0)
A37: TOTAL | B37: =SUM(B29:B36) | C37: =SUM(C29:C36)
A40: Per-Project Resource Breakdown
A41: Only the Project ID is entered — all other values are formulas referencing source sheets
A43: ETE-124 | B43: =INDEX('Project Portfolio'!$B:$B,MATCH($A43,'Project Portfolio'!$A:$A,0)) | D43: Priority: | E43: =INDEX('Project Portfolio'!$H:$H,MATCH($A43,'Project Portfolio'!$A:$A,0)) | F43: Est Hrs: | G43: =INDEX('Project Portfolio'!$R:$R,MATCH($A43,'Project Portfolio'!$A:$A,0))
B45: Alloc % | C45: Discovery | D45: Planning | E45: Design | F45: Build | G45: Test | H45: Deploy/Hypercare | I45: Total Hrs | J45: Days
A46: Phase Hours | C46: =$G$43*B14 | D46: =$G$43*C14 | E46: =$G$43*D14 | F46: =$G$43*E14 | G46: =$G$43*F14 | H46: =$G$43*G14 | I46: =SUM(C46:H46)
A47: IT Business Analyst/SME | B47: =INDEX('Project Portfolio'!$T:$T,MATCH($A$43,'Project Portfolio'!$A:$A,0)) | C47: =$G$43*B47*RM_Assumptions!B23 | D47: =$G$43*B47*RM_Assumptions!C23 | E47: =$G$43*B47*RM_Assumptions!D23 | F47: =$G$43*B47*RM_Assumptions!E23 | G47: =$G$43*B47*RM_Assumptions!F23 | H47: =$G$43*B47*RM_Assumptions!G23 | I47: =SUM(C47:H47) | J47: =IFERROR(I47/($D$31*0.85)*5,0)
...

Sheet Capacity Summary
A1: ETE IT PMO — Capacity Summary
A2: All supply/headcount values are formulas — change Team Roster and this sheet recalculates
A4: Team Size | C4: Active Projects | E4: Weekly Supply | G4: Weekly Demand | I4: Utilization
A5: =B18 | C5: 15 | E5: =TEXT(D18,"0")&" hrs" | G5: =TEXT(E18,"0")&" hrs" | I5: =IFERROR(TEXT(E18/D18,"0%"),"0%")
A8: Supply vs. Demand by Role
A9: Role | B9: Headcount | C9: Per-Person (hrs/wk) | D9: Team Supply (hrs/wk) | E9: Team Demand (hrs/wk) | F9: Gap (hrs/wk) | G9: Utilization | H9: Status
A10: Project Manager | B10: =COUNTIF('Team Roster'!$B$4:$B$26,"Project Manager") | C10: =IFERROR(AVERAGEIFS('Team Roster'!$K$4:$K$26,'Team Roster'!$B$4:$B$26,"Project Manager"),0) | D10: =SUMIFS('Team Roster'!$K$4:$K$26,'Team Roster'!$B$4:$B$26,"Project Manager") | E10: 0 | F10: =D10-E10 | G10: =IFERROR(E10/D10,0) | H10: =IF(G10>=1,"RED",IF(G10>=0.8,"YELLOW","GREEN"))
A11: DBA | B11: =COUNTIF('Team Roster'!$B$4:$B$26,"DBA") | C11: =IFERROR(AVERAGEIFS('Team Roster'!$K$4:$K$26,'Team Roster'!$B$4:$B$26,"DBA"),0) | D11: =SUMIFS('Team Roster'!$K$4:$K$26,'Team Roster'!$B$4:$B$26,"DBA") | E11: 0 | F11: =D11-E11 | G11: =IFERROR(E11/D11,0) | H11: =IF(G11>=1,"RED",IF(G11>=0.8,"YELLOW","GREEN"))
A12: IT Business Analyst/SME | B12: =COUNTIF('Team Roster'!$B$4:$B$26,"Business Analyst") | C12: =IFERROR(AVERAGEIFS('Team Roster'!$K$4:$K$26,'Team Roster'!$B$4:$B$26,"Business Analyst"),0) | D12: =SUMIFS('Team Roster'!$K$4:$K$26,'Team Roster'!$B$4:$B$26,"Business Analyst") | E12: 0 | F12: =D12-E12 | G12: =IFERROR(E12/D12,0) | H12: =IF(G12>=1,"RED",IF(G12>=0.8,"YELLOW","GREEN"))
A13: IT Functional Analyst | B13: =COUNTIF('Team Roster'!$B$4:$B$26,"Functional") | C13: =IFERROR(AVERAGEIFS('Team Roster'!$K$4:$K$26,'Team Roster'!$B$4:$B$26,"Functional"),0) | D13: =SUMIFS('Team Roster'!$K$4:$K$26,'Team Roster'!$B$4:$B$26,"Functional") | E13: 0 | F13: =D13-E13 | G13: =IFERROR(E13/D13,0) | H13: =IF(G13>=1,"RED",IF(G13>=0.8,"YELLOW","GREEN"))
A14: IT Tech Analyst/Developer | B14: =COUNTIF('Team Roster'!$B$4:$B$26,"Technical") | C14: =IFERROR(AVERAGEIFS('Team Roster'!$K$4:$K$26,'Team Roster'!$B$4:$B$26,"Technical"),0) | D14: =SUMIFS('Team Roster'!$K$4:$K$26,'Team Roster'!$B$4:$B$26,"Technical") | E14: 0 | F14: =D14-E14 | G14: =IFERROR(E14/D14,0) | H14: =IF(G14>=1,"RED",IF(G14>=0.8,"YELLOW","GREEN"))
A15: Developer | B15: =COUNTIF('Team Roster'!$B$4:$B$26,"Developer") | C15: =IFERROR(AVERAGEIFS('Team Roster'!$K$4:$K$26,'Team Roster'!$B$4:$B$26,"Developer"),0) | D15: =SUMIFS('Team Roster'!$K$4:$K$26,'Team Roster'!$B$4:$B$26,"Developer") | E15: 0 | F15: =D15-E15 | G15: =IFERROR(E15/D15,0) | H15: =IF(G15>=1,"RED",IF(G15>=0.8,"YELLOW","GREEN"))
A16: Infrastructure | B16: =COUNTIF('Team Roster'!$B$4:$B$26,"Infrastructure") | C16: =IFERROR(AVERAGEIFS('Team Roster'!$K$4:$K$26,'Team Roster'!$B$4:$B$26,"Infrastructure"),0) | D16: =SUMIFS('Team Roster'!$K$4:$K$26,'Team Roster'!$B$4:$B$26,"Infrastructure") | E16: 0 | F16: =D16-E16 | G16: =IFERROR(E16/D16,0) | H16: =IF(G16>=1,"RED",IF(G16>=0.8,"YELLOW","GREEN"))
A17: WMS Consultant | B17: =COUNTIF('Team Roster'!$B$4:$B$26,"WMS Consultant") | C17: =IFERROR(AVERAGEIFS('Team Roster'!$K$4:$K$26,'Team Roster'!$B$4:$B$26,"WMS Consultant"),0) | D17: =SUMIFS('Team Roster'!$K$4:$K$26,'Team Roster'!$B$4:$B$26,"WMS Consultant") | E17: 0 | F17: =D17-E17 | G17: =IFERROR(E17/D17,0) | H17: =IF(G17>=1,"RED",IF(G17>=0.8,"YELLOW","GREEN"))
A18: TOTAL | B18: =SUM(B10:B17) | D18: =SUM(D10:D17) | E18: =SUM(E10:E17) | F18: =D18-E18
A21: Active Projects — Bottom-Up Duration Estimates
A22: ID | B22: Project | C22: Priority | D22: Est Hrs | E22: Allocated | F22: Duration (days) | G22: Bottleneck Role | H22: Start | I22: End
A23: ETE-124 | B23: Clean Up Return Loads | C23: Highest | D23: 200 | E23: 220 | G23: IT Business Analyst/SME | H23: TBD | I23: TBD
A24: ETE-37 | B24: Magic Search in BuyETE | C24: Highest | D24: 40 | E24: 40 | G24: IT Business Analyst/SME | H24: TBD | I24: TBD
A25: ETE-97 | B25: Standard Order Process Notifications | C25: Highest | D25: 200 | E25: 170 | G25: IT Business Analyst/SME | H25: TBD | I25: TBD
A26: ETE-68 | B26: Catalog API Rust2Python | C26: High | D26: 640 | E26: 544 | G26: IT Business Analyst/SME | H26: 11/17/2025 | I26: 04/24/2026
A27: ETE-19 | B27: Changes to AR Aging Report | C27: High | D27: 120 | E27: 120 | G27: IT Business Analyst/SME | H27: 02/23/2026 | I27: 04/17/2026
A28: ETE-83 | B28: Customer Master Data Cleanup | C28: High | D28: 1480 | E28: 148 | G28: IT Business Analyst/SME | H28: 10/14/2025 | I28: 06/01/2026
A29: ETE-48 | B29: System Connection Syteline-VKS | C29: High | D29: 240 | E29: 84 | G29: IT Business Analyst/SME | H29: 02/15/2026 | I29: 06/30/2026
A30: ETE-100 | B30: ATSG Expired Members Self-Payment | C30: Medium | D30: 200 | E30: 170 | G30: IT Business Analyst/SME | H30: TBD | I30: TBD
A31: ETE-49 | B31: Marketing: STE Rewards Tier | C31: Medium | D31: 240 | E31: 204 | G31: IT Business Analyst/SME | H31: TBD | I31: TBD
A32: ETE-7 | B32: Outsourced Unit Core Accounting | C32: Medium | D32: 640 | E32: 640 | G32: IT Business Analyst/SME | H32: TBD | I32: TBD
A33: ETE-16 | B33: Partial Pay w/ CC from WMERP | C33: Medium | D33: 120 | E33: 120 | G33: IT Business Analyst/SME | H33: TBD | I33: TBD
A34: ETE-52 | B34: SWIMS/Syteline Reporting | C34: Medium | D34: 40 | E34: 34 | G34: IT Business Analyst/SME | H34: TBD | I34: TBD

Sheet Role Capacity Planner
A1: ETE IT PMO — Role Capacity Planner
A2: Scenario table uses formulas — change Team Roster and scenarios recalculate
A4: Headcount Scenario Analysis
A5: Shows current state and impact of adding +1, +2, or +3 people per role
A7: Role | B7: Current Headcount | C7: Per-Person (hrs/wk) | D7: Team Supply (hrs/wk) | E7: Demand (hrs/wk) | F7: Current Util % | G7: Status | H7: +1 Person Supply | I7: +1 Person Util % | J7: +1 Status | K7: +2 People Supply | L7: +2 People Util % | M7: +2 Status | N7: +3 People Supply | O7: +3 People Util % | P7: +3 Status
A8: Project Manager | B8: =COUNTIF('Team Roster'!$B$4:$B$26,"Project Manager") | C8: =IFERROR(AVERAGEIFS('Team Roster'!$K$4:$K$26,'Team Roster'!$B$4:$B$26,"Project Manager"),0) | D8: =SUMIFS('Team Roster'!$K$4:$K$26,'Team Roster'!$B$4:$B$26,"Project Manager") | E8: 0 | F8: =IFERROR(E8/D8,0) | G8: =IF(F8>=1,"OVER",IF(F8>=0.85,"AT LIMIT",IF(F8>=0.8,"TIGHT","OK"))) | H8: =D8+C8*1 | I8: =IFERROR(E8/H8,0) | J8: =IF(I8>=1,"OVER",IF(I8>=0.85,"AT LIMIT",IF(I8>=0.8,"TIGHT","OK"))) | K8: =D8+C8*2 | L8: =IFERROR(E8/K8,0) | M8: =IF(L8>=1,"OVER",IF(L8>=0.85,"AT LIMIT",IF(L8>=0.8,"TIGHT","OK"))) | N8: =D8+C8*3 | O8: =IFERROR(E8/N8,0) | P8: =IF(O8>=1,"OVER",IF(O8>=0.85,"AT LIMIT",IF(O8>=0.8,"TIGHT","OK")))
A9: DBA | B9: =COUNTIF('Team Roster'!$B$4:$B$26,"DBA") | C9: =IFERROR(AVERAGEIFS('Team Roster'!$K$4:$K$26,'Team Roster'!$B$4:$B$26,"DBA"),0) | D9: =SUMIFS('Team Roster'!$K$4:$K$26,'Team Roster'!$B$4:$B$26,"DBA") | E9: 0 | F9: =IFERROR(E9/D9,0) | G9: =IF(F9>=1,"OVER",IF(F9>=0.85,"AT LIMIT",IF(F9>=0.8,"TIGHT","OK"))) | H9: =D9+C9*1 | I9: =IFERROR(E9/H9,0) | J9: =IF(I9>=1,"OVER",IF(I9>=0.85,"AT LIMIT",IF(I9>=0.8,"TIGHT","OK"))) | K9: =D9+C9*2 | L9: =IFERROR(E9/K9,0) | M9: =IF(L9>=1,"OVER",IF(L9>=0.85,"AT LIMIT",IF(L9>=0.8,"TIGHT","OK"))) | N9: =D9+C9*3 | O9: =IFERROR(E9/N9,0) | P9: =IF(O9>=1,"OVER",IF(O9>=0.85,"AT LIMIT",IF(O9>=0.8,"TIGHT","OK")))
A10: IT Business Analyst/SME | B10: =COUNTIF('Team Roster'!$B$4:$B$26,"Business Analyst") | C10: =IFERROR(AVERAGEIFS('Team Roster'!$K$4:$K$26,'Team Roster'!$B$4:$B$26,"Business Analyst"),0) | D10: =SUMIFS('Team Roster'!$K$4:$K$26,'Team Roster'!$B$4:$B$26,"Business Analyst") | E10: 0 | F10: =IFERROR(E10/D10,0) | G10: =IF(F10>=1,"OVER",IF(F10>=0.85,"AT LIMIT",IF(F10>=0.8,"TIGHT","OK"))) | H10: =D10+C10*1 | I10: =IFERROR(E10/H10,0) | J10: =IF(I10>=1,"OVER",IF(I10>=0.85,"AT LIMIT",IF(I10>=0.8,"TIGHT","OK"))) | K10: =D10+C10*2 | L10: =IFERROR(E10/K10,0) | M10: =IF(L10>=1,"OVER",IF(L10>=0.85,"AT LIMIT",IF(L10>=0.8,"TIGHT","OK"))) | N10: =D10+C10*3 | O10: =IFERROR(E10/N10,0) | P10: =IF(O10>=1,"OVER",IF(O10>=0.85,"AT LIMIT",IF(O10>=0.8,"TIGHT","OK")))
A11: IT Functional Analyst | B11: =COUNTIF('Team Roster'!$B$4:$B$26,"Functional") | C11: =IFERROR(AVERAGEIFS('Team Roster'!$K$4:$K$26,'Team Roster'!$B$4:$B$26,"Functional"),0) | D11: =SUMIFS('Team Roster'!$K$4:$K$26,'Team Roster'!$B$4:$B$26,"Functional") | E11: 0 | F11: =IFERROR(E11/D11,0) | G11: =IF(F11>=1,"OVER",IF(F11>=0.85,"AT LIMIT",IF(F11>=0.8,"TIGHT","OK"))) | H11: =D11+C11*1 | I11: =IFERROR(E11/H11,0) | J11: =IF(I11>=1,"OVER",IF(I11>=0.85,"AT LIMIT",IF(I11>=0.8,"TIGHT","OK"))) | K11: =D11+C11*2 | L11: =IFERROR(E11/K11,0) | M11: =IF(L11>=1,"OVER",IF(L11>=0.85,"AT LIMIT",IF(L11>=0.8,"TIGHT","OK"))) | N11: =D11+C11*3 | O11: =IFERROR(E11/N11,0) | P11: =IF(O11>=1,"OVER",IF(O11>=0.85,"AT LIMIT",IF(O11>=0.8,"TIGHT","OK")))
A12: IT Tech Analyst/Developer | B12: =COUNTIF('Team Roster'!$B$4:$B$26,"Technical") | C12: =IFERROR(AVERAGEIFS('Team Roster'!$K$4:$K$26,'Team Roster'!$B$4:$B$26,"Technical"),0) | D12: =SUMIFS('Team Roster'!$K$4:$K$26,'Team Roster'!$B$4:$B$26,"Technical") | E12: 0 | F12: =IFERROR(E12/D12,0) | G12: =IF(F12>=1,"OVER",IF(F12>=0.85,"AT LIMIT",IF(F12>=0.8,"TIGHT","OK"))) | H12: =D12+C12*1 | I12: =IFERROR(E12/H12,0) | J12: =IF(I12>=1,"OVER",IF(I12>=0.85,"AT LIMIT",IF(I12>=0.8,"TIGHT","OK"))) | K12: =D12+C12*2 | L12: =IFERROR(E12/K12,0) | M12: =IF(L12>=1,"OVER",IF(L12>=0.85,"AT LIMIT",IF(L12>=0.8,"TIGHT","OK"))) | N12: =D12+C12*3 | O12: =IFERROR(E12/N12,0) | P12: =IF(O12>=1,"OVER",IF(O12>=0.85,"AT LIMIT",IF(O12>=0.8,"TIGHT","OK")))
A13: Developer | B13: =COUNTIF('Team Roster'!$B$4:$B$26,"Developer") | C13: =IFERROR(AVERAGEIFS('Team Roster'!$K$4:$K$26,'Team Roster'!$B$4:$B$26,"Developer"),0) | D13: =SUMIFS('Team Roster'!$K$4:$K$26,'Team Roster'!$B$4:$B$26,"Developer") | E13: 0 | F13: =IFERROR(E13/D13,0) | G13: =IF(F13>=1,"OVER",IF(F13>=0.85,"AT LIMIT",IF(F13>=0.8,"TIGHT","OK"))) | H13: =D13+C13*1 | I13: =IFERROR(E13/H13,0) | J13: =IF(I13>=1,"OVER",IF(I13>=0.85,"AT LIMIT",IF(I13>=0.8,"TIGHT","OK"))) | K13: =D13+C13*2 | L13: =IFERROR(E13/K13,0) | M13: =IF(L13>=1,"OVER",IF(L13>=0.85,"AT LIMIT",IF(L13>=0.8,"TIGHT","OK"))) | N13: =D13+C13*3 | O13: =IFERROR(E13/N13,0) | P13: =IF(O13>=1,"OVER",IF(O13>=0.85,"AT LIMIT",IF(O13>=0.8,"TIGHT","OK")))
A14: Infrastructure | B14: =COUNTIF('Team Roster'!$B$4:$B$26,"Infrastructure") | C14: =IFERROR(AVERAGEIFS('Team Roster'!$K$4:$K$26,'Team Roster'!$B$4:$B$26,"Infrastructure"),0) | D14: =SUMIFS('Team Roster'!$K$4:$K$26,'Team Roster'!$B$4:$B$26,"Infrastructure") | E14: 0 | F14: =IFERROR(E14/D14,0) | G14: =IF(F14>=1,"OVER",IF(F14>=0.85,"AT LIMIT",IF(F14>=0.8,"TIGHT","OK"))) | H14: =D14+C14*1 | I14: =IFERROR(E14/H14,0) | J14: =IF(I14>=1,"OVER",IF(I14>=0.85,"AT LIMIT",IF(I14>=0.8,"TIGHT","OK"))) | K14: =D14+C14*2 | L14: =IFERROR(E14/K14,0) | M14: =IF(L14>=1,"OVER",IF(L14>=0.85,"AT LIMIT",IF(L14>=0.8,"TIGHT","OK"))) | N14: =D14+C14*3 | O14: =IFERROR(E14/N14,0) | P14: =IF(O14>=1,"OVER",IF(O14>=0.85,"AT LIMIT",IF(O14>=0.8,"TIGHT","OK")))
A15: WMS Consultant | B15: =COUNTIF('Team Roster'!$B$4:$B$26,"WMS Consultant") | C15: =IFERROR(AVERAGEIFS('Team Roster'!$K$4:$K$26,'Team Roster'!$B$4:$B$26,"WMS Consultant"),0) | D15: =SUMIFS('Team Roster'!$K$4:$K$26,'Team Roster'!$B$4:$B$26,"WMS Consultant") | E15: 0 | F15: =IFERROR(E15/D15,0) | G15: =IF(F15>=1,"OVER",IF(F15>=0.85,"AT LIMIT",IF(F15>=0.8,"TIGHT","OK"))) | H15: =D15+C15*1 | I15: =IFERROR(E15/H15,0) | J15: =IF(I15>=1,"OVER",IF(I15>=0.85,"AT LIMIT",IF(I15>=0.8,"TIGHT","OK"))) | K15: =D15+C15*2 | L15: =IFERROR(E15/K15,0) | M15: =IF(L15>=1,"OVER",IF(L15>=0.85,"AT LIMIT",IF(L15>=0.8,"TIGHT","OK"))) | N15: =D15+C15*3 | O15: =IFERROR(E15/N15,0) | P15: =IF(O15>=1,"OVER",IF(O15>=0.85,"AT LIMIT",IF(O15>=0.8,"TIGHT","OK")))
A18: Impact on Project Durations (days)
A19: How project durations change if we add 1 person to a role (bottleneck relief)
A21: ID | B21: Project | C21: Est Hrs | D21: Current Days | E21: +1 Project Manager Days | F21: +1 DBA Days | G21: +1 Business Analyst Days | H21: +1 Functional Analyst Days | I21: +1 Tech Analyst Days | J21: +1 Developer Days | K21: +1 Infrastructure Days | L21: +1 WMS Consultant Days
A22: ETE-124 | B22: Clean Up Return Loads | C22: 200
A23: ETE-37 | B23: Magic Search in BuyETE | C23: 40
A24: ETE-97 | B24: Standard Order Process Notifications | C24: 200
A25: ETE-68 | B25: Catalog API Rust2Python | C25: 640
A26: ETE-19 | B26: Changes to AR Aging Report | C26: 120
A27: ETE-83 | B27: Customer Master Data Cleanup | C27: 1480
A28: ETE-48 | B28: System Connection Syteline-VKS | C28: 240
A29: ETE-100 | B29: ATSG Expired Members Self-Payment | C29: 200
A30: ETE-49 | B30: Marketing: STE Rewards Tier | C30: 240
A31: ETE-7 | B31: Outsourced Unit Core Accounting | C31: 640
A32: ETE-16 | B32: Partial Pay w/ CC from WMERP | C32: 120
A33: ETE-52 | B33: SWIMS/Syteline Reporting | C33: 40
A36: Weekly Role Utilization Heatmap
A37: Role-level utilization by week — shows when role groups get hot
A38: Overloaded (>100%) | B38: At Capacity (80-100%) | C38: Healthy (<80%)
A40: Role | B40: Headcount | C40: Supply (hrs/wk) | D40: 04/06 | E40: 04/13 | F40: 04/20 | G40: 04/27 | H40: 05/04 | I40: 05/11 | J40: 05/18 | K40: 05/25 | L40: 06/01 | M40: 06/08 | N40: 06/15 | O40: 06/22 | P40: 06/29 | Q40: 07/06 | R40: 07/13 | S40: 07/20 | T40: 07/27 | U40: 08/03 | V40: 08/10 | W40: 08/17 | X40: 08/24 | Y40: 08/31 | Z40: 09/07 | AA40: 09/14 | AB40: 09/21 | AC40: 09/28
A41: Project Manager | B41: 3 | C41: 0 | D41: 0 | E41: 0 | F41: 0 | G41: 0 | H41: 0 | I41: 0 | J41: 0 | K41: 0 | L41: 0 | M41: 0 | N41: 0 | O41: 0 | P41: 0 | Q41: 0 | R41: 0 | S41: 0 | T41: 0 | U41: 0 | V41: 0 | W41: 0 | X41: 0 | Y41: 0 | Z41: 0 | AA41: 0 | AB41: 0 | AC41: 0
A42: IT Business Analyst/SME | B42: 4 | C42: 0 | D42: 0 | E42: 0 | F42: 0 | G42: 0 | H42: 0 | I42: 0 | J42: 0 | K42: 0 | L42: 0 | M42: 0 | N42: 0 | O42: 0 | P42: 0 | Q42: 0 | R42: 0 | S42: 0 | T42: 0 | U42: 0 | V42: 0 | W42: 0 | X42: 0 | Y42: 0 | Z42: 0 | AA42: 0 | AB42: 0 | AC42: 0
A43: IT Functional Analyst | B43: 2 | C43: 0 | D43: 0 | E43: 0 | F43: 0 | G43: 0 | H43: 0 | I43: 0 | J43: 0 | K43: 0 | L43: 0 | M43: 0 | N43: 0 | O43: 0 | P43: 0 | Q43: 0 | R43: 0 | S43: 0 | T43: 0 | U43: 0 | V43: 0 | W43: 0 | X43: 0 | Y43: 0 | Z43: 0 | AA43: 0 | AB43: 0 | AC43: 0
A44: IT Tech Analyst/Developer | B44: 5 | C44: 0 | D44: 0 | E44: 0 | F44: 0 | G44: 0 | H44: 0 | I44: 0 | J44: 0 | K44: 0 | L44: 0 | M44: 0 | N44: 0 | O44: 0 | P44: 0 | Q44: 0 | R44: 0 | S44: 0 | T44: 0 | U44: 0 | V44: 0 | W44: 0 | X44: 0 | Y44: 0 | Z44: 0 | AA44: 0 | AB44: 0 | AC44: 0
A45: Developer | B45: 4 | C45: 0 | D45: 0 | E45: 0 | F45: 0 | G45: 0 | H45: 0 | I45: 0 | J45: 0 | K45: 0 | L45: 0 | M45: 0 | N45: 0 | O45: 0 | P45: 0 | Q45: 0 | R45: 0 | S45: 0 | T45: 0 | U45: 0 | V45: 0 | W45: 0 | X45: 0 | Y45: 0 | Z45: 0 | AA45: 0 | AB45: 0 | AC45: 0

Sheet Project Portfolio
A1: ETE IT PMO — Project Portfolio
A3: ID | B3: Project Name | C3: Type | D3: Business Portfolio | E3: Sponsor/Leader | F3: Project Health | G3: % Complete | H3: Priority | I3: Start Date | J3: Est. End Date | K3: Actual/Updated End | L3: Team | M3: PM | N3: BA | O3: Functional | P3: Technical | Q3: Developer | R3: T-Shirt Size | S3: Est. Hours | T3: Est. Cost Range | U3: BA % | V3: Functional % | W3: Technical % | X3: Developer % | Y3: Infrastructure % | Z3: DBA % | AA3: PM % | AB3: WMS % | AC3: Notes | AD3: Sort Order
A4: ETE-83 | B4: Customer Master Data Cleanup | C4: Key Initiative | D4: Sales & Distribution | E4: Tom Vierling | F4: 📋 NEEDS TECHNICAL SPEC | G4: 0.15 | H4: High | I4: 45944 | J4: 46174 | L4: Systems Applications | M4: Emily Fridley | N4: Audrey Debaere | Q4: Alex Young | R4: XXL: > 640 Hours | S4: 1480 | T4: =$R4*65 | U4: 0.1 | AC4: Completed Q1 | AD4: =IF(OR(ISNUMBER(SEARCH("POSTPONED",$F4)),ISNUMBER(SEARCH("NOT APPROVED",$F4))),2,IF(ISNUMBER(SEARCH("COMPLETE",$F4)),3,1))
A5: ETE-48 | B5: System Connection Syteline-VKS | C5: Key Initiative | D5: Engineering | E5: Ray Trumble | F5: 🟢 ON TRACK | G5: 0.1 | H5: High | I5: 46068 | J5: 46203 | L5: Synnergie | M5: Emily Fridley | N5: Audrey Debaere | Q5: Alex Young | R5: L: 160-320 Hours | S5: 240 | T5: =$R5*65 | U5: 0.1 | AA5: 0.25 | AD5: =IF(OR(ISNUMBER(SEARCH("POSTPONED",$F5)),ISNUMBER(SEARCH("NOT APPROVED",$F5))),2,IF(ISNUMBER(SEARCH("COMPLETE",$F5)),3,1))
A6: ETE-68 | B6: Catalog API Rust2Python | C6: Key Initiative | D6: Information Technology | E6: Jim Koscielniak | F6: 🟢 ON TRACK | G6: 0.13 | H6: High | I6: 45978 | J6: 46136 | L6: Systems Applications | M6: Emily Fridley | N6: Audrey Debaere | P6: Colin Olson | Q6: Alex Young | R6: XXL: > 640 Hours | S6: 640 | T6: =$R6*65 | U6: 0.1 | X6: 0.75 | AD6: =IF(OR(ISNUMBER(SEARCH("POSTPONED",$F6)),ISNUMBER(SEARCH("NOT APPROVED",$F6))),2,IF(ISNUMBER(SEARCH("COMPLETE",$F6)),3,1))
A7: ETE-43 | B7: Data Security - Microsoft Purview | C7: Key Initiative | D7: Information Technology | E7: Jim Koscielniak | F7: 🟢 ON TRACK | G7: 0 | H7: High | I7: 46055 | J7: 46203 | L7: Infrastructure | M7: Emily Fridley | N7: Audrey Debaere | Q7: Alex Young | S7: 0 | T7: =$R7*65 | U7: 0.1 | AD7: =IF(OR(ISNUMBER(SEARCH("POSTPONED",$F7)),ISNUMBER(SEARCH("NOT APPROVED",$F7))),2,IF(ISNUMBER(SEARCH("COMPLETE",$F7)),3,1))
A8: ETE-19 | B8: Changes to AR Aging Report | C8: Enhancement | D8: Finance | E8: Tom Newell | F8: 🟢 ON TRACK | G8: 0 | H8: High | I8: 46076 | J8: 46129 | L8: Synnergie | M8: Emily Fridley | N8: Audrey Debaere | O8: Ajay Kumar | P8: Bhavya Reddy | Q8: Alex Young | R8: M: 80-160 Hours | S8: 120 | T8: =$R8*65 | U8: 0.1 | V8: 0.25 | W8: 0.65 | AD8: =IF(OR(ISNUMBER(SEARCH("POSTPONED",$F8)),ISNUMBER(SEARCH("NOT APPROVED",$F8))),2,IF(ISNUMBER(SEARCH("COMPLETE",$F8)),3,1))
A9: ETE-49 | B9: Marketing: STE Rewards Tier | C9: Enhancement | D9: Sales & Distribution | E9: Tom Vierling | F9: 📋 NEEDS TECHNICAL SPEC | G9: 0 | H9: Medium | L9: Systems Applications | M9: Emily Fridley | N9: Audrey Debaere | Q9: Alex Young | R9: L: 160-320 Hours | S9: 240 | T9: =$R9*65 | U9: 0.1 | V9: 0 | W9: 0 | X9: 0.75 | Y9: 0 | Z9: 0 | AA9: 0 | AB9: 0 | AD9: =IF(OR(ISNUMBER(SEARCH("POSTPONED",$F9)),ISNUMBER(SEARCH("NOT APPROVED",$F9))),2,IF(ISNUMBER(SEARCH("COMPLETE",$F9)),3,1))
A10: ETE-7 | B10: Outsourced Unit Core Accounting | C10: Enhancement | D10: Finance | E10: Tom Newell | F10: 📋 NEEDS FUNCTIONAL SPEC | G10: 0 | H10: Medium | L10: Synnergie | M10: Emily Fridley | N10: Audrey Debaere | Q10: Alex Young | R10: XXL: > 640 Hours | S10: 640 | T10: =$R10*65 | U10: 0.1 | V10: 0.25 | W10: 0.65 | X10: 0 | Y10: 0 | Z10: 0 | AA10: 0 | AB10: 0 | AC10: 8-9 month project | AD10: =IF(OR(ISNUMBER(SEARCH("POSTPONED",$F10)),ISNUMBER(SEARCH("NOT APPROVED",$F10))),2,IF(ISNUMBER(SEARCH("COMPLETE",$F10)),3,1))
A11: ETE-52 | B11: SWIMS/Syteline Reporting | C11: Enhancement | D11: Supply Chain | E11: Jon Besherse | F11: 📋 NEEDS TECHNICAL SPEC | G11: 0 | H11: Medium | L11: Systems Applications | M11: Emily Fridley | N11: Audrey Debaere | Q11: Alex Young | R11: S: < 80 Hours | S11: 40 | T11: =$R11*65 | U11: 0.1 | V11: 0 | W11: 0 | X11: 0.75 | Y11: 0 | Z11: 0 | AA11: 0 | AB11: 0 | AD11: =IF(OR(ISNUMBER(SEARCH("POSTPONED",$F11)),ISNUMBER(SEARCH("NOT APPROVED",$F11))),2,IF(ISNUMBER(SEARCH("COMPLETE",$F11)),3,1))
A12: ETE-16 | B12: Partial Pay w/ CC from WMERP | C12: Enhancement | D12: Finance | E12: Tom Newell | F12: ⚪ NOT STARTED | G12: 0 | H12: Medium | L12: Synnergie | M12: Emily Fridley | N12: Audrey Debaere | Q12: Alex Young | R12: M: 80-160 Hours | S12: 120 | T12: =$R12*65 | U12: 0.1 | V12: 0.25 | W12: 0.65 | X12: 0 | Y12: 0 | Z12: 0 | AA12: 0 | AB12: 0 | AD12: =IF(OR(ISNUMBER(SEARCH("POSTPONED",$F12)),ISNUMBER(SEARCH("NOT APPROVED",$F12))),2,IF(ISNUMBER(SEARCH("COMPLETE",$F12)),3,1))
A13: ETE-37 | B13: Magic Search in BuyETE | C13: Enhancement | D13: Sales & Distribution | E13: Tom Vierling | F13: 📋 NEEDS TECHNICAL SPEC | G13: 0 | H13: Highest | L13: Systems Applications | M13: Emily Fridley | N13: Audrey Debaere | Q13: Alex Young | R13: S: < 80 Hours | S13: 40 | T13: =$R13*65 | U13: 0.1 | V13: 0.25 | W13: 0 | X13: 0.65 | Y13: 0 | Z13: 0 | AA13: 0 | AB13: 0 | AD13: =IF(OR(ISNUMBER(SEARCH("POSTPONED",$F13)),ISNUMBER(SEARCH("NOT APPROVED",$F13))),2,IF(ISNUMBER(SEARCH("COMPLETE",$F13)),3,1))
A14: ETE-97 | B14: Standard Order Process Notifications | C14: Enhancement | D14: Sales & Distribution | E14: Tom Vierling | F14: ⚪ NOT STARTED | G14: 0 | H14: Highest | L14: Systems Applications | M14: Emily Fridley | N14: Audrey Debaere | Q14: Alex Young | S14: 200 | T14: =$R14*65 | U14: 0.1 | V14: 0 | W14: 0 | X14: 0.75 | Y14: 0 | Z14: 0 | AA14: 0 | AB14: 0 | AD14: =IF(OR(ISNUMBER(SEARCH("POSTPONED",$F14)),ISNUMBER(SEARCH("NOT APPROVED",$F14))),2,IF(ISNUMBER(SEARCH("COMPLETE",$F14)),3,1))
A15: ETE-100 | B15: ATSG Expired Members Self-Payment | C15: Enhancement | D15: Sales & Distribution | E15: Tom Vierling | F15: 📋 NEEDS FUNCTIONAL SPEC | G15: 0 | H15: Medium | L15: Systems Applications | M15: Emily Fridley | N15: Audrey Debaere | Q15: Alex Young | S15: 200 | T15: =$R15*65 | U15: 0.1 | V15: 0 | W15: 0 | X15: 0.75 | Y15: 0 | Z15: 0 | AA15: 0 | AB15: 0 | AD15: =IF(OR(ISNUMBER(SEARCH("POSTPONED",$F15)),ISNUMBER(SEARCH("NOT APPROVED",$F15))),2,IF(ISNUMBER(SEARCH("COMPLETE",$F15)),3,1))
A16: ETE-124 | B16: Clean Up Return Loads | C16: Enhancement | D16: Finance | E16: Tom Newell | F16: 📋 NEEDS TECHNICAL SPEC | G16: 0 | H16: Highest | L16: Synnergie | M16: Emily Fridley | N16: Audrey Debaere | Q16: Alex Young | S16: 200 | T16: =$R16*65 | U16: 0.1 | V16: 0.25 | W16: 0.75 | X16: 0 | Y16: 0 | Z16: 0 | AA16: 0 | AB16: 0 | AD16: =IF(OR(ISNUMBER(SEARCH("POSTPONED",$F16)),ISNUMBER(SEARCH("NOT APPROVED",$F16))),2,IF(ISNUMBER(SEARCH("COMPLETE",$F16)),3,1))
AD17: =IF(OR(ISNUMBER(SEARCH("POSTPONED",$F17)),ISNUMBER(SEARCH("NOT APPROVED",$F17))),2,IF(ISNUMBER(SEARCH("COMPLETE",$F17)),3,1))
A18: ETE-58 | B18: Transfer Order Moved Items to Transit Location | C18: Enhancement | D18: Finance | E18: Jim Young | F18: ⏸️ POSTPONED | G18: 0 | AD18: =IF(OR(ISNUMBER(SEARCH("POSTPONED",$F18)),ISNUMBER(SEARCH("NOT APPROVED",$F18))),2,IF(ISNUMBER(SEARCH("COMPLETE",$F18)),3,1))
A19: ETE-51 | B19: RMA Credit Memo on Ghost Check-In | C19: Enhancement | D19: Finance | E19: Tom Newell | F19: ⏸️ POSTPONED | G19: 0 | AD19: =IF(OR(ISNUMBER(SEARCH("POSTPONED",$F19)),ISNUMBER(SEARCH("NOT APPROVED",$F19))),2,IF(ISNUMBER(SEARCH("COMPLETE",$F19)),3,1))
A20: ETE-59 | B20: Reconcile BridgePay CC Transactions | C20: Enhancement | D20: Finance | E20: Tom Newell | F20: ⏸️ POSTPONED | G20: 0 | AD20: =IF(OR(ISNUMBER(SEARCH("POSTPONED",$F20)),ISNUMBER(SEARCH("NOT APPROVED",$F20))),2,IF(ISNUMBER(SEARCH("COMPLETE",$F20)),3,1))
A21: ETE-60 | B21: EDI Payments Not Posting on Background | C21: Enhancement | D21: Finance | E21: Tom Newell | F21: ⏸️ POSTPONED | G21: 0 | AD21: =IF(OR(ISNUMBER(SEARCH("POSTPONED",$F21)),ISNUMBER(SEARCH("NOT APPROVED",$F21))),2,IF(ISNUMBER(SEARCH("COMPLETE",$F21)),3,1))
A22: ETE-61 | B22: Accum Deposits Received Field | C22: Bug | D22: Finance | E22: Tom Newell | F22: ⏸️ POSTPONED | G22: 0 | AD22: =IF(OR(ISNUMBER(SEARCH("POSTPONED",$F22)),ISNUMBER(SEARCH("NOT APPROVED",$F22))),2,IF(ISNUMBER(SEARCH("COMPLETE",$F22)),3,1))
A23: ETE-86 | B23: Allow TCM Core Receiving to Post | C23: Enhancement | D23: Engineering | E23: Ray Trumble | F23: ⏸️ POSTPONED | G23: 0 | AD23: =IF(OR(ISNUMBER(SEARCH("POSTPONED",$F23)),ISNUMBER(SEARCH("NOT APPROVED",$F23))),2,IF(ISNUMBER(SEARCH("COMPLETE",$F23)),3,1))
A24: ETE-34 | B24: Salesforce BDR Application & Process Implementation | C24: Enhancement | D24: Sales & Distribution | E24: Tom Vierling | F24: ⏸️ POSTPONED | G24: 0 | AD24: =IF(OR(ISNUMBER(SEARCH("POSTPONED",$F24)),ISNUMBER(SEARCH("NOT APPROVED",$F24))),2,IF(ISNUMBER(SEARCH("COMPLETE",$F24)),3,1))
A25: ETE-35 | B25: BuyETE Ability for Customers to Save Quotes | C25: Enhancement | D25: Sales & Distribution | E25: Tom Vierling | F25: ⏸️ POSTPONED | G25: 0 | AD25: =IF(OR(ISNUMBER(SEARCH("POSTPONED",$F25)),ISNUMBER(SEARCH("NOT APPROVED",$F25))),2,IF(ISNUMBER(SEARCH("COMPLETE",$F25)),3,1))
A26: ETE-33 | B26: EDI 3PL Locations | C26: Enhancement | D26: Sales & Distribution | E26: Tom Vierling | F26: ⏸️ POSTPONED | G26: 0 | H26: High | L26: Systems Applications | N26: Jim Young | R26: M: 80-160 Hours | S26: 120 | AD26: =IF(OR(ISNUMBER(SEARCH("POSTPONED",$F26)),ISNUMBER(SEARCH("NOT APPROVED",$F26))),2,IF(ISNUMBER(SEARCH("COMPLETE",$F26)),3,1))
A27: ETE-67 | B27: Avalara Tax Issues | C27: Enhancement | D27: Finance | E27: Tom Newell | F27: ✅ COMPLETE | G27: 1 | H27: Highest | I27: 46057 | J27: 46080 | L27: Synnergie | N27: Audrey Debaere | O27: Deepak Gudwani | P27: Sangamesh Koti | R27: M: 80-160 Hours | S27: 120 | T27: =$R27*65 | U27: 0.1 | V27: 0.25 | W27: 0.75 | AD27: =IF(OR(ISNUMBER(SEARCH("POSTPONED",$F27)),ISNUMBER(SEARCH("NOT APPROVED",$F27))),2,IF(ISNUMBER(SEARCH("COMPLETE",$F27)),3,1))
A28: ETE-14 | B28: Installed Return RMA Type | C28: Enhancement | D28: Supply Chain | E28: Jon Besherse | F28: ✅ COMPLETE | G28: 1 | H28: Highest | I28: 46083 | J28: 46101 | L28: Synnergie | N28: Audrey Debaere | R28: M: 80-160 Hours | S28: 120 | T28: =$R28*65 | U28: 0.1 | V28: 0.25 | W28: 0.65 | AD28: =IF(OR(ISNUMBER(SEARCH("POSTPONED",$F28)),ISNUMBER(SEARCH("NOT APPROVED",$F28))),2,IF(ISNUMBER(SEARCH("COMPLETE",$F28)),3,1))
A29: ETE-70 | B29: Nutanix (Replace VMware) | C29: Key Initiative | D29: Information Technology | E29: Jim Koscielniak | F29: ✅ COMPLETE | G29: 1 | H29: Highest | I29: 45992 | J29: 46102 | L29: Infrastructure | P29: Michael House | S29: 120 | T29: =$R29*65 | U29: 0.1 | Y29: 0.5 | AD29: =IF(OR(ISNUMBER(SEARCH("POSTPONED",$F29)),ISNUMBER(SEARCH("NOT APPROVED",$F29))),2,IF(ISNUMBER(SEARCH("COMPLETE",$F29)),3,1))
A30: ETE-65 | B30: Rebuild Vendor Portal | C30: Enhancement | D30: Sales & Distribution | E30: Tom Vierling | F30: ✅ COMPLETE | G30: 1 | H30: High | I30: 45957 | J30: 46031 | K30: 46068 | L30: Systems Applications | N30: Jim Young | P30: Jonathon Gonzalez | R30: S: < 80 Hours | S30: 60 | T30: 11895 | AD30: =IF(OR(ISNUMBER(SEARCH("POSTPONED",$F30)),ISNUMBER(SEARCH("NOT APPROVED",$F30))),2,IF(ISNUMBER(SEARCH("COMPLETE",$F30)),3,1))
A31: ETE-69 | B31: Core Plan Optimization | C31: Key Initiative | D31: Supply Chain | E31: Jon Besherse | F31: ✅ COMPLETE | G31: 1 | H31: High | I31: 45973 | J31: 46045 | K31: 46045 | L31: Synnergie | N31: Audrey Debaere | P31: Ravindra Reddy | R31: L: 160-320 Hours | S31: 360 | T31: 16120 | AD31: =IF(OR(ISNUMBER(SEARCH("POSTPONED",$F31)),ISNUMBER(SEARCH("NOT APPROVED",$F31))),2,IF(ISNUMBER(SEARCH("COMPLETE",$F31)),3,1))
A32: ETE-31 | B32: Restocking Fees Added to RMA Credit Memo | C32: Enhancement | D32: Finance | E32: Tom Newell | F32: ✅ COMPLETE | G32: 1 | H32: High | I32: 45648 | J32: 46059 | K32: 46081 | L32: Synnergie | N32: Audrey Debaere | P32: Bhavya Reddy | R32: L: 160-320 Hours | S32: 310 | T32: 1625 | AD32: =IF(OR(ISNUMBER(SEARCH("POSTPONED",$F32)),ISNUMBER(SEARCH("NOT APPROVED",$F32))),2,IF(ISNUMBER(SEARCH("COMPLETE",$F32)),3,1))
A33: ETE-45 | B33: VB Bin Printer Integration | C33: Enhancement | D33: Engineering | E33: Ray Trumble | F33: ✅ COMPLETE | G33: 1 | H33: High | I33: 45950 | J33: 46073 | K33: 46073 | L33: Synnergie | N33: Cristian Varelas | P33: Sangamesh Koti | R33: M: 80-160 Hours | S33: 160 | T33: 260 | AD33: =IF(OR(ISNUMBER(SEARCH("POSTPONED",$F33)),ISNUMBER(SEARCH("NOT APPROVED",$F33))),2,IF(ISNUMBER(SEARCH("COMPLETE",$F33)),3,1))
A34: ETE-42 | B34: Gear Screen - Improved Production Oversight | C34: Key Initiative | D34: Production | E34: Ari Rosengarten | F34: ✅ COMPLETE | G34: 1 | H34: High | I34: 46034 | J34: 46058 | K34: 46081 | L34: Synnergie | N34: Cristian Varelas | P34: Vishnu Premen | R34: M: 80-160 Hours | S34: 120 | AC34: NAPA not ready | AD34: =IF(OR(ISNUMBER(SEARCH("POSTPONED",$F34)),ISNUMBER(SEARCH("NOT APPROVED",$F34))),2,IF(ISNUMBER(SEARCH("COMPLETE",$F34)),3,1))
A35: ETE-72 | B35: Fortigate ZTNA - EMS Setup | C35: Key Initiative | D35: Information Technology | E35: Jim Koscielniak | F35: ✅ COMPLETE | G35: 1 | H35: High | I35: 46003 | J35: 46022 | K35: 46080 | L35: Infrastructure | P35: Justin Senour | S35: 0 | AD35: =IF(OR(ISNUMBER(SEARCH("POSTPONED",$F35)),ISNUMBER(SEARCH("NOT APPROVED",$F35))),2,IF(ISNUMBER(SEARCH("COMPLETE",$F35)),3,1))
A36: ETE-71 | B36: One Drive Migration | C36: Key Initiative | D36: Information Technology | E36: Jim Koscielniak | F36: ✅ COMPLETE | G36: 1 | H36: High | I36: 46013 | J36: 46059 | K36: 46068 | L36: Infrastructure | P36: Michael House | S36: 0 | AD36: =IF(OR(ISNUMBER(SEARCH("POSTPONED",$F36)),ISNUMBER(SEARCH("NOT APPROVED",$F36))),2,IF(ISNUMBER(SEARCH("COMPLETE",$F36)),3,1))
A37: ETE-87 | B37: Production Dashboard | C37: Enhancement | D37: Production | E37: Ari Rosengarten | F37: ✅ COMPLETE | G37: 1 | H37: High | L37: Systems Applications | R37: S: < 80 Hours | S37: 40 | AD37: =IF(OR(ISNUMBER(SEARCH("POSTPONED",$F37)),ISNUMBER(SEARCH("NOT APPROVED",$F37))),2,IF(ISNUMBER(SEARCH("COMPLETE",$F37)),3,1))
A38: ETE-88 | B38: Return Load Phase 2 | C38: Key Initiative | D38: Finance | E38: Tom Newell | F38: ✅ COMPLETE | G38: 1 | H38: High | I38: 45957 | J38: 46020 | K38: 46031 | L38: Synnergie | N38: Audrey Debaere | P38: Sangamesh Koti | S38: 320 | AD38: =IF(OR(ISNUMBER(SEARCH("POSTPONED",$F38)),ISNUMBER(SEARCH("NOT APPROVED",$F38))),2,IF(ISNUMBER(SEARCH("COMPLETE",$F38)),3,1))
A39: ETE-73 | B39: Teal Parts Daily Inventory Feed | C39: Enhancement | D39: Sales & Distribution | E39: Tom Vierling | F39: ✅ COMPLETE | G39: 1 | H39: Highest | L39: Systems Applications | N39: Cristian Varelas | R39: S: < 80 Hours | S39: 40 | AD39: =IF(OR(ISNUMBER(SEARCH("POSTPONED",$F39)),ISNUMBER(SEARCH("NOT APPROVED",$F39))),2,IF(ISNUMBER(SEARCH("COMPLETE",$F39)),3,1))
A40: ETE-10 | B40: Upload Utility for Planning Fields | C40: Enhancement | D40: Supply Chain | E40: Tom Green | F40: ✅ COMPLETE | G40: 0.1 | H40: Highest | L40: Synnergie | M40: Emily Fridley | N40: Audrey Debaere | Q40: Alex Young | R40: S: < 80 Hours | S40: 80 | AD40: =IF(OR(ISNUMBER(SEARCH("POSTPONED",$F40)),ISNUMBER(SEARCH("NOT APPROVED",$F40))),2,IF(ISNUMBER(SEARCH("COMPLETE",$F40)),3,1))
A41: ETE-32 | B41: Form: Cash App SQL Fix | C41: Enhancement | D41: Finance | E41: Tom Newell | F41: ✅ COMPLETE | G41: 1 | H41: High | L41: Synnergie | N41: Audrey Debaere | R41: L: 160-320 Hours | S41: 320 | AD41: =IF(OR(ISNUMBER(SEARCH("POSTPONED",$F41)),ISNUMBER(SEARCH("NOT APPROVED",$F41))),2,IF(ISNUMBER(SEARCH("COMPLETE",$F41)),3,1))
...

Sheet Team Roster
A1: ETE IT PMO — Team Roster & Capacity
A3: Resource | B3: Role | C3: Team | D3: Vendor | E3: Resource Classification | F3: Rate/Hour | G3: Weekly Hrs Available | H3: Support Reserve % | I3: Project Capacity % | J3: Support Reserve (hrs/wk) | K3: Project Capacity (hrs/wk)
A4: Ajay Kumar | B4: Functional | C4: ERP | D4: Synnergie | E4: MSA | F4: 65 | G4: 35 | H4: 0.4 | I4: =1-H4 | J4: =G4*H4 | K4: =G4*I4
A5: Ravindra Reddy | B5: Technical | C5: ERP | D5: Synnergie | E5: MSA | F5: 65 | G5: 35 | H5: 0.4 | I5: =1-H5 | J5: =G5*H5 | K5: =G5*I5
A6: Vishnu Premen | B6: Technical | C6: ERP | D6: Synnergie | E6: =IF(D6="Synnergie","T&M",IF(D6="Watermark","MSA",IF(D6="ETE","Internal",""))) | F6: 65 | G6: 35 | H6: 0.4 | I6: =1-H6 | J6: =G6*H6 | K6: =G6*I6
A7: Deepak Gudwani | B7: Functional | C7: ERP | D7: Synnergie | E7: =IF(D7="Synnergie","T&M",IF(D7="Watermark","MSA",IF(D7="ETE","Internal",""))) | F7: 65 | G7: 35 | H7: 0.4 | I7: =1-H7 | J7: =G7*H7 | K7: =G7*I7
A8: Sangamesh Koti | B8: Technical | C8: ERP | D8: Synnergie | E8: T&M | F8: 65 | G8: 35 | H8: 0 | I8: =1-H8 | J8: =G8*H8 | K8: =G8*I8
A9: Bhavya Reddy | B9: Technical | C9: ERP | D9: Synnergie | E9: =IF(D9="Synnergie","T&M",IF(D9="Watermark","MSA",IF(D9="ETE","Internal",""))) | F9: 65 | G9: 35 | H9: 0 | I9: =1-H9 | J9: =G9*H9 | K9: =G9*I9
A10: Sarath Yeturu | B10: Technical | C10: ERP | D10: Synnergie | E10: MSA | F10: 65 | G10: 35 | H10: 0.6 | I10: =1-H10 | J10: =G10*H10 | K10: =G10*I10
A11: Vinod Bollepally | B11: DBA | C11: ERP | D11: Synnergie | E11: MSA | F11: 65 | G11: 35 | H11: 0.8 | I11: =1-H11 | J11: =G11*H11 | K11: =G11*I11
A12: Jim Young | B12: Business Analyst | C12: Business Analysts | D12: ETE | E12: =IF(D12="Synnergie","T&M",IF(D12="Watermark","MSA",IF(D12="ETE","Internal",""))) | F12: 65 | G12: 40 | H12: 0.6 | I12: =1-H12 | J12: =G12*H12 | K12: =G12*I12
A13: Alex Young | B13: Developer | C13: Systems Applications | D13: ETE | E13: =IF(D13="Synnergie","T&M",IF(D13="Watermark","MSA",IF(D13="ETE","Internal",""))) | F13: 65 | G13: 25 | H13: 0.5 | I13: =1-H13 | J13: =G13*H13 | K13: =G13*I13
A14: Nick Smith | B14: Developer | C14: Systems Applications | D14: ETE | E14: =IF(D14="Synnergie","T&M",IF(D14="Watermark","MSA",IF(D14="ETE","Internal",""))) | F14: 65 | G14: 25 | H14: 0.4 | I14: =1-H14 | J14: =G14*H14 | K14: =G14*I14
A15: Colin Olson | B15: Developer | C15: Systems Applications | D15: ETE | E15: =IF(D15="Synnergie","T&M",IF(D15="Watermark","MSA",IF(D15="ETE","Internal",""))) | F15: 65 | G15: 25 | H15: 0.1 | I15: =1-H15 | J15: =G15*H15 | K15: =G15*I15
A16: Jonathon Gonzalez | B16: Developer | C16: Systems Applications | D16: ETE | E16: =IF(D16="Synnergie","T&M",IF(D16="Watermark","MSA",IF(D16="ETE","Internal",""))) | F16: 65 | G16: 25 | H16: 0.25 | I16: =1-H16 | J16: =G16*H16 | K16: =G16*I16
A17: Audrey Debaere | B17: Business Analyst | C17: Business Analysts | D17: ETE | E17: =IF(D17="Synnergie","T&M",IF(D17="Watermark","MSA",IF(D17="ETE","Internal",""))) | F17: 65 | G17: 35 | H17: 0.5 | I17: =1-H17 | J17: =G17*H17 | K17: =G17*I17
A18: Cristian Varelas | B18: Business Analyst | C18: Business Analysts | D18: ETE | E18: =IF(D18="Synnergie","T&M",IF(D18="Watermark","MSA",IF(D18="ETE","Internal",""))) | F18: 65 | G18: 35 | H18: 0.2 | I18: =1-H18 | J18: =G18*H18 | K18: =G18*I18
A19: Ryan Picado | B19: Business Analyst | C19: Business Analysts | D19: ETE | E19: =IF(D19="Synnergie","T&M",IF(D19="Watermark","MSA",IF(D19="ETE","Internal",""))) | F19: 65 | G19: 35 | H19: 0.5 | I19: =1-H19 | J19: =G19*H19 | K19: =G19*I19
A20: Emily Fridley | B20: Project Manager | C20: PMO | D20: ETE | E20: =IF(D20="Synnergie","T&M",IF(D20="Watermark","MSA",IF(D20="ETE","Internal",""))) | F20: 65 | G20: 35 | H20: 0.5 | I20: =1-H20 | J20: =G20*H20 | K20: =G20*I20
A21: Brett Anderson | B21: Project Manager | C21: PMO | D21: ETE | E21: =IF(D21="Synnergie","T&M",IF(D21="Watermark","MSA",IF(D21="ETE","Internal",""))) | F21: 65 | G21: 35 | H21: 0.25 | I21: =1-H21 | J21: =G21*H21 | K21: =G21*I21
A22: Bettina Kotico | B22: Project Manager | C22: PMO | D22: Kayana | E22: T&M | F22: 65 | G22: 32 | H22: 0.68 | I22: =1-H22 | J22: =G22*H22 | K22: =G22*I22
A23: Donna Wiedemeier | B23: WMS Consultant | C23: WMS | D23: Watermark | E23: T&M | F23: 65 | G23: 35 | H23: 0.6 | I23: =1-H23 | J23: =G23*H23 | K23: =G23*I23
A24: Justin Senour | B24: Infrastructure | C24: Infrastructure | D24: ETE | E24: =IF(D24="Synnergie","T&M",IF(D24="Watermark","MSA",IF(D24="ETE","Internal",""))) | F24: 65 | G24: 40 | H24: 0.6 | I24: =1-H24 | J24: =G24*H24 | K24: =G24*I24
A25: Michael House | B25: Infrastructure | C25: Infrastructure | D25: ETE | E25: =IF(D25="Synnergie","T&M",IF(D25="Watermark","MSA",IF(D25="ETE","Internal",""))) | F25: 65 | G25: 40 | H25: 0.6 | I25: =1-H25 | J25: =G25*H25 | K25: =G25*I25
A26: Andrew Shaefer | B26: Infrastructure | C26: Infrastructure | D26: ETE | E26: =IF(D26="Synnergie","T&M",IF(D26="Watermark","MSA",IF(D26="ETE","Internal",""))) | F26: 65 | G26: 40 | H26: 0.6 | I26: =1-H26 | J26: =G26*H26 | K26: =G26*I26
A27: TOTALS | G27: =SUM(G4:G26) | H27: =IF(G27>0,J27/G27,0) | I27: =IF(G27>0,K27/G27,0) | J27: =SUM(J4:J26) | K27: =SUM(K4:K26)

Sheet RM_Assumptions
A1: ETE IT PMO — Resource Model Assumptions
A2: All blue inputs are configurable. Change values to run scenarios.
A4: TIME ALLOCATION MODEL
A5: Parameter | B5: Value | C5: Unit | D5: Notes
A6: Base Hours / Week | B6: 40 | C6: hrs | D6: Standard work week
A7: Admin Allocation | B7: 0.1 | C7: % | D7: Meetings, email, admin tasks
A8: Break/Fix Allocation | B8: 0.1 | C8: % | D8: Support tickets, break/fix work
A9: Project Allocation | B9: 0.8 | C9: % | D9: Time available for project work
A10: Available Project Hrs / Person / Wk | B10: =B6*B9 | C10: hrs | D10: Base Hrs × Project %
A11: Allocation Check (must = 100%) | B11: =B7+B8+B9
A12: Max Projects / Person | B12: 3 | C12: projects | D12: Constraint: no one on more than 3
A14: SDLC PHASE WEIGHTS
B15: Discovery | C15: Planning | D15: Design | E15: Build | F15: Test | G15: Deploy/Hypercare | H15: Total
A16: % of Project Effort | B16: 0.1 | C16: 0.1 | D16: 0.15 | E16: 0.3 | F16: 0.2 | G16: 0.15 | H16: =SUM(B16:G16)
A18: ROLE EFFORT BY SDLC PHASE
A19: % of phase effort per role (rows don't need to sum to 100% — each role works a share of each phase independently)
A20: Role | B20: Discovery | C20: Planning | D20: Design | E20: Build | F20: Test | G20: Deploy/Hypercare | H20: Avg Effort
A21: PM | B21: 0.1 | C21: 0.25 | D21: 0.15 | E21: 0.2 | F21: 0.2 | G21: 0.1 | H21: =SUMPRODUCT(B21:G21,B$16:G$16)
A22: DBA | B22: 0.05 | C22: 0.1 | D22: 0.3 | E22: 0.25 | F22: 0.2 | G22: 0.1 | H22: =SUMPRODUCT(B22:G22,B$16:G$16)
A23: IT Business Analyst/SME | B23: 0.3 | C23: 0.2 | D23: 0.2 | E23: 0.1 | F23: 0.15 | G23: 0.05 | H23: =SUMPRODUCT(B23:G23,B$16:G$16)
A24: IT Functional Analyst | B24: 0.2 | C24: 0.1 | D24: 0.3 | E24: 0.15 | F24: 0.15 | G24: 0.1 | H24: =SUMPRODUCT(B24:G24,B$16:G$16)
A25: IT Tech Analyst/Developer | B25: 0.05 | C25: 0.1 | D25: 0.2 | E25: 0.4 | F25: 0.15 | G25: 0.1 | H25: =SUMPRODUCT(B25:G25,B$16:G$16)
A26: Developer | B26: 0 | C26: 0.05 | D26: 0.1 | E26: 0.5 | F26: 0.25 | G26: 0.1 | H26: =SUMPRODUCT(B26:G26,B$16:G$16)
A27: Infrastructure | B27: 0.05 | C27: 0.1 | D27: 0.15 | E27: 0.2 | F27: 0.15 | G27: 0.35 | H27: =SUMPRODUCT(B27:G27,B$16:G$16)
A28: WMS Consultant | B28: 0.1 | C28: 0.15 | D28: 0.1 | E28: 0.1 | F28: 0.05 | G28: 0.5 | H28: =SUMPRODUCT(B28:G28,B$16:G$16)
A29: Phase Total (all roles) | B29: =SUM(B21:B28) | C29: =SUM(C21:C28) | D29: =SUM(D21:D28) | E29: =SUM(E21:E28) | F29: =SUM(F21:F28) | G29: =SUM(G21:G28)
A31: SUPPLY: TEAM CAPACITY BY ROLE
A32: Role | B32: Headcount | C32: Hrs/Wk (Gross) | D32: Project Hrs/Wk | E32: Notes
A33: PM | B33: =COUNTIF('Team Roster'!B$4:B$26,"Project Manager") | C33: =SUMIF('Team Roster'!B$4:B$26,"Project Manager",'Team Roster'!G$4:G$26) | D33: =C33*$B$9 | E33: Roster role: "Project Manager"
A34: DBA | B34: =COUNTIF('Team Roster'!B$4:B$26,"DBA") | C34: =SUMIF('Team Roster'!B$4:B$26,"DBA",'Team Roster'!G$4:G$26) | D34: =C34*$B$9 | E34: Roster role: "DBA"
A35: IT Business Analyst/SME | B35: =COUNTIF('Team Roster'!B$4:B$26,"Business Analyst") | C35: =SUMIF('Team Roster'!B$4:B$26,"Business Analyst",'Team Roster'!G$4:G$26) | D35: =C35*$B$9 | E35: Roster role: "Business Analyst"
A36: IT Functional Analyst | B36: =COUNTIF('Team Roster'!B$4:B$26,"Functional") | C36: =SUMIF('Team Roster'!B$4:B$26,"Functional",'Team Roster'!G$4:G$26) | D36: =C36*$B$9 | E36: Roster role: "Functional"
A37: IT Tech Analyst/Developer | B37: =COUNTIF('Team Roster'!B$4:B$26,"Technical") | C37: =SUMIF('Team Roster'!B$4:B$26,"Technical",'Team Roster'!G$4:G$26) | D37: =C37*$B$9 | E37: Roster role: "Technical"
A38: Developer | B38: =COUNTIF('Team Roster'!B$4:B$26,"Developer") | C38: =SUMIF('Team Roster'!B$4:B$26,"Developer",'Team Roster'!G$4:G$26) | D38: =C38*$B$9 | E38: Roster role: "Developer"
A39: Infrastructure | B39: =COUNTIF('Team Roster'!B$4:B$26,"Infrastructure") | C39: =SUMIF('Team Roster'!B$4:B$26,"Infrastructure",'Team Roster'!G$4:G$26) | D39: =C39*$B$9 | E39: Roster role: "Infrastructure"
A40: WMS Consultant | B40: =COUNTIF('Team Roster'!B$4:B$26,"WMS Consultant") | C40: =SUMIF('Team Roster'!B$4:B$26,"WMS Consultant",'Team Roster'!G$4:G$26) | D40: =C40*$B$9 | E40: Roster role: "WMS Consultant"
A41: TOTAL | B41: =SUM(B33:B40) | C41: =SUM(C33:C40) | D41: =SUM(D33:D40)

Sheet Capacity Heatmap
A1: ETE IT PMO — Weekly Capacity Heatmap (Per Person)
A2: Overloaded (>100%) | B2: At Capacity (80-100%) | C2: Healthy (<80%)
A4: Resource | B4: Role | C4: Team | D4: Capacity (hrs/wk) | E4: 04/06 | F4: 04/13 | G4: 04/20 | H4: 04/27 | I4: 05/04 | J4: 05/11 | K4: 05/18 | L4: 05/25 | M4: 06/01 | N4: 06/08 | O4: 06/15 | P4: 06/22 | Q4: 06/29 | R4: 07/06 | S4: 07/13 | T4: 07/20 | U4: 07/27 | V4: 08/03 | W4: 08/10 | X4: 08/17 | Y4: 08/24 | Z4: 08/31 | AA4: 09/07 | AB4: 09/14 | AC4: 09/21 | AD4: 09/28
A5: Bettina Kotico | B5: Project Manager | C5: PMO | D5: 0 | E5: 0 | F5: 0 | G5: 0 | H5: 0 | I5: 0 | J5: 0 | K5: 0 | L5: 0 | M5: 0 | N5: 0 | O5: 0 | P5: 0 | Q5: 0 | R5: 0 | S5: 0 | T5: 0 | U5: 0 | V5: 0 | W5: 0 | X5: 0 | Y5: 0 | Z5: 0 | AA5: 0 | AB5: 0 | AC5: 0 | AD5: 0
A6: Brett Anderson | B6: Project Manager | C6: PMO | D6: 0 | E6: 0 | F6: 0 | G6: 0 | H6: 0 | I6: 0 | J6: 0 | K6: 0 | L6: 0 | M6: 0 | N6: 0 | O6: 0 | P6: 0 | Q6: 0 | R6: 0 | S6: 0 | T6: 0 | U6: 0 | V6: 0 | W6: 0 | X6: 0 | Y6: 0 | Z6: 0 | AA6: 0 | AB6: 0 | AC6: 0 | AD6: 0
A7: Emily Fridley | B7: Project Manager | C7: PMO | D7: 0 | E7: 0 | F7: 0 | G7: 0 | H7: 0 | I7: 0 | J7: 0 | K7: 0 | L7: 0 | M7: 0 | N7: 0 | O7: 0 | P7: 0 | Q7: 0 | R7: 0 | S7: 0 | T7: 0 | U7: 0 | V7: 0 | W7: 0 | X7: 0 | Y7: 0 | Z7: 0 | AA7: 0 | AB7: 0 | AC7: 0 | AD7: 0
A8: Vinod Bollepally | B8: DBA | C8: ERP | D8: 0 | E8: 0 | F8: 0 | G8: 0 | H8: 0 | I8: 0 | J8: 0 | K8: 0 | L8: 0 | M8: 0 | N8: 0 | O8: 0 | P8: 0 | Q8: 0 | R8: 0 | S8: 0 | T8: 0 | U8: 0 | V8: 0 | W8: 0 | X8: 0 | Y8: 0 | Z8: 0 | AA8: 0 | AB8: 0 | AC8: 0 | AD8: 0
A9: Audrey Debaere | B9: Business Analyst | C9: Business Analysts | D9: 0 | E9: 0 | F9: 0 | G9: 0 | H9: 0 | I9: 0 | J9: 0 | K9: 0 | L9: 0 | M9: 0 | N9: 0 | O9: 0 | P9: 0 | Q9: 0 | R9: 0 | S9: 0 | T9: 0 | U9: 0 | V9: 0 | W9: 0 | X9: 0 | Y9: 0 | Z9: 0 | AA9: 0 | AB9: 0 | AC9: 0 | AD9: 0
A10: Cristian Varelas | B10: Business Analyst | C10: Business Analysts | D10: 0 | E10: 0 | F10: 0 | G10: 0 | H10: 0 | I10: 0 | J10: 0 | K10: 0 | L10: 0 | M10: 0 | N10: 0 | O10: 0 | P10: 0 | Q10: 0 | R10: 0 | S10: 0 | T10: 0 | U10: 0 | V10: 0 | W10: 0 | X10: 0 | Y10: 0 | Z10: 0 | AA10: 0 | AB10: 0 | AC10: 0 | AD10: 0
A11: Jim Young | B11: Business Analyst | C11: Business Analysts | D11: 0 | E11: 0 | F11: 0 | G11: 0 | H11: 0 | I11: 0 | J11: 0 | K11: 0 | L11: 0 | M11: 0 | N11: 0 | O11: 0 | P11: 0 | Q11: 0 | R11: 0 | S11: 0 | T11: 0 | U11: 0 | V11: 0 | W11: 0 | X11: 0 | Y11: 0 | Z11: 0 | AA11: 0 | AB11: 0 | AC11: 0 | AD11: 0
A12: Ryan Picado | B12: Business Analyst | C12: Business Analysts | D12: 0 | E12: 0 | F12: 0 | G12: 0 | H12: 0 | I12: 0 | J12: 0 | K12: 0 | L12: 0 | M12: 0 | N12: 0 | O12: 0 | P12: 0 | Q12: 0 | R12: 0 | S12: 0 | T12: 0 | U12: 0 | V12: 0 | W12: 0 | X12: 0 | Y12: 0 | Z12: 0 | AA12: 0 | AB12: 0 | AC12: 0 | AD12: 0
A13: Ajay Kumar | B13: Functional | C13: ERP | D13: 0 | E13: 0 | F13: 0 | G13: 0 | H13: 0 | I13: 0 | J13: 0 | K13: 0 | L13: 0 | M13: 0 | N13: 0 | O13: 0 | P13: 0 | Q13: 0 | R13: 0 | S13: 0 | T13: 0 | U13: 0 | V13: 0 | W13: 0 | X13: 0 | Y13: 0 | Z13: 0 | AA13: 0 | AB13: 0 | AC13: 0 | AD13: 0
A14: Deepak Gudwani | B14: Functional | C14: ERP | D14: 0 | E14: 0 | F14: 0 | G14: 0 | H14: 0 | I14: 0 | J14: 0 | K14: 0 | L14: 0 | M14: 0 | N14: 0 | O14: 0 | P14: 0 | Q14: 0 | R14: 0 | S14: 0 | T14: 0 | U14: 0 | V14: 0 | W14: 0 | X14: 0 | Y14: 0 | Z14: 0 | AA14: 0 | AB14: 0 | AC14: 0 | AD14: 0
A15: Bhavya Reddy | B15: Technical | C15: ERP | D15: 0 | E15: 0 | F15: 0 | G15: 0 | H15: 0 | I15: 0 | J15: 0 | K15: 0 | L15: 0 | M15: 0 | N15: 0 | O15: 0 | P15: 0 | Q15: 0 | R15: 0 | S15: 0 | T15: 0 | U15: 0 | V15: 0 | W15: 0 | X15: 0 | Y15: 0 | Z15: 0 | AA15: 0 | AB15: 0 | AC15: 0 | AD15: 0
A16: Ravindra Reddy | B16: Technical | C16: ERP | D16: 0 | E16: 0 | F16: 0 | G16: 0 | H16: 0 | I16: 0 | J16: 0 | K16: 0 | L16: 0 | M16: 0 | N16: 0 | O16: 0 | P16: 0 | Q16: 0 | R16: 0 | S16: 0 | T16: 0 | U16: 0 | V16: 0 | W16: 0 | X16: 0 | Y16: 0 | Z16: 0 | AA16: 0 | AB16: 0 | AC16: 0 | AD16: 0
... A27: Donna Wiedemeier | B27: WMS Consultant | C27: WMS | D27: 0 | E27: 0 | F27: 0 | G27: 0 | H27: 0 | I27: 0 | J27: 0 | K27: 0 | L27: 0 | M27: 0 | N27: 0 | O27: 0 | P27: 0 | Q27: 0 | R27: 0 | S27: 0 | T27: 0 | U27: 0 | V27: 0 | W27: 0 | X27: 0 | Y27: 0 | Z27: 0 | AA27: 0 | AB27: 0 | AC27: 0 | AD27: 0

Sheet RM_Gantt
A1: ETE IT PMO — Project Gantt Chart
A2: Generated: 03/31/2026 | Color = priority
AF3: NOW
A4: ID | B4: Project Name | C4: Priority | D4: Est Hrs | E4: Start | F4: End | G4: Dur | H4: 10/13 | I4: 10/20 | J4: 10/27 | K4: 11/03 | L4: 11/10 | M4: 11/17 | N4: 11/24 | O4: 12/01 | P4: 12/08 | Q4: 12/15 | R4: 12/22 | S4: 12/29 | T4: 01/05 | U4: 01/12 | V4: 01/19 | W4: 01/26 | X4: 02/02 | Y4: 02/09 | Z4: 02/16 | AA4: 02/23 | AB4: 03/02 | AC4: 03/09 | AD4: 03/16 | AE4: 03/23 | AF4: 03/30 | AG4: 04/06 | AH4: 04/13 | AI4: 04/20 | AJ4: 04/27 | AK4: 05/04 | AL4: 05/11 | AM4: 05/18 | AN4: 05/25 | AO4: 06/01 | AP4: 06/08 | AQ4: 06/15 | AR4: 06/22 | AS4: 06/29 | AT4: 07/06 | AU4: 07/13 | AV4: 07/20 | AW4: 07/27
A5: ETE-124 | B5: Clean Up Return Loads | C5: Highest | D5: 200 | E5: TBD | F5: TBD
A6: ETE-37 | B6: Magic Search in BuyETE | C6: Highest | D6: 40 | E6: TBD | F6: TBD
A7: ETE-97 | B7: Standard Order Process Notifications | C7: Highest | D7: 200 | E7: TBD | F7: TBD
A8: ETE-10 | B8: Upload Utility for Planning Fields | C8: Highest | D8: 80 | E8: TBD | F8: TBD
A9: ETE-68 | B9: Catalog API Rust2Python | C9: High | D9: 640 | E9: 11/17/2025 | F9: 04/24/2026 | G9: 23w
A10: ETE-19 | B10: Changes to AR Aging Report | C10: High | D10: 120 | E10: 02/23/2026 | F10: 04/17/2026 | G10: 8w
A11: ETE-83 | B11: Customer Master Data Cleanup | C11: High | D11: 1480 | E11: 10/14/2025 | F11: 06/01/2026 | G11: 33w
A12: ETE-76 | B12: FedEx Web Services API | C12: High | D12: 40 | E12: 03/03/2026 | F12: 03/13/2026 | G12: 1w
A13: ETE-48 | B13: System Connection Syteline-VKS | C13: High | D13: 240 | E13: 02/15/2026 | F13: 06/30/2026 | G13: 19w
A14: ETE-100 | B14: ATSG Expired Members Self-Payment | C14: Medium | D14: 200 | E14: TBD | F14: TBD
A15: ETE-49 | B15: Marketing: STE Rewards Tier | C15: Medium | D15: 240 | E15: TBD | F15: TBD
A16: ETE-7 | B16: Outsourced Unit Core Accounting | C16: Medium | D16: 640 | E16: TBD | F16: TBD
A17: ETE-16 | B17: Partial Pay w/ CC from WMERP | C17: Medium | D17: 120 | E17: TBD | F17: TBD
A18: ETE-52 | B18: SWIMS/Syteline Reporting | C18: Medium | D18: 40 | E18: TBD | F18: TBD
A20: Legend: | B20: Highest | D20: High | F20: Medium | H20: Low

Sheet RM_Guide
A1: ETE IT PMO — Resource Model Guide
A2: A plain-English explanation of how the Resource Model works, what each sheet does, and how to use it.
A4: THE BIG PICTURE
A5: What is this? | B5: A set of 4 connected sheets that answer: "Do we have enough people for all these projects, and when will we be in trouble?"
A6: Why does it exist? | B6: The Portfolio shows WHAT projects we have. The Resource Model shows WHETHER we can actually staff them — and when bottlenecks will hit.
A7: Who should use it? | B7: PMO leads for weekly planning, resource decisions, and "what if" scenario testing (hiring, project delays, reprioritization).
A8: How do the sheets connect? | B8: RM_Assumptions (rules) → RM_Demand (how much work) → RM_SupplyVsDemand (big picture) → RM_WeeklyHeatmap (when exactly).
A9: What are the blue cells? | B9: Any cell with a blue/light blue background is an INPUT you can change. These are your scenario levers — adjust them and the model recalculates automatically.
A11: SHEET-BY-SHEET EXPLANATION
A13: 📋 RM_Assumptions | B13: "What are our rules?" — This is the control panel for the whole model.
A14: Time Allocation (rows 6-12) | B14: Each person works 40 hrs/week, but not all of it goes to projects. Admin (10%) and Break/Fix support (10%) eat into that, leaving 80% = 32 hrs/week for project work. You can change these percentages.
A15: SDLC Phase Weights (row 16) | B15: A project isn't evenly spread. It's 10% Discovery → 10% Planning → 15% Design → 30% Build → 20% Test → 15% Deploy. These must add to 100%. Change them to match your actual project lifecycle.
A16: Role Effort by Phase (rows 21-28) | B16: THIS IS THE KEY INSIGHT. A DBA isn't equally busy throughout a project. They barely touch Discovery (5%) but are heavily loaded in Build (30%). A BA is the opposite — 30% in Discovery, only 10% in Build. These percentages drive the weekly demand spikes in the heatmap.
A17: Team Supply (rows 30-38) | B17: Auto-counts headcount and hours from the Team Roster. You don't edit these — they update when Team Roster changes.
A19: 📊 RM_Demand | B19: "How much work is coming?" — Calculates total demand from active projects.
A20: Active Projects (rows 6-18) | B20: Automatically pulls all non-complete, non-postponed projects from the Portfolio. You don't edit these rows — they update when Portfolio changes.
A21: Total Demand by Role (rows 24-30) | B21: For each role, adds up: (Project Est. Hours × Role Allocation %) across all active projects. Shows you the total hours each role needs to deliver.
A22: Project × Role Detail (rows 36-48) | B22: A breakdown showing exactly how many hours each project needs from each role. Useful for seeing which projects are driving the most demand.
A24: ⚖️ RM_SupplyVsDemand | B24: "Are we OK overall?" — A summary scorecard comparing supply to demand.
A25: Capacity Scorecard (rows 5-7) | B25: The headline numbers: Total Supply hrs/wk, Total Demand hrs/wk, Net Gap (+ means surplus, - means deficit), and Overall Utilization %.
A26: By Role (rows 11-17) | B26: Same comparison broken out by role. Color-coded: green = fine, yellow = tight, red = over capacity. This tells you WHERE the problem is.
... A32: The Heatmap (rows 34-40) | B32: The payoff. Each cell shows utilization % for one role in one week. Green (<80%) = fine. Yellow (80-99%) = getting tight. Red (100%+) = overloaded, need to act. Demand shifts week-to-week because the model knows which SDLC phase each project is in.
A35: HOW TO RUN SCENARIOS
A36: "What if we hire another DBA?" | B36: Go to RM_WeeklyHeatmap → cell C11 (DBA Add/Remove) → type 1. The DBA row in the heatmap will drop from red to green. If it works, you've justified the hire.
A37: "What if we delay a project?" | B37: Go to RM_WeeklyHeatmap → find the project in rows 17-29 → change its Start Date (column D) or End Date (column E). The heatmap will shift that project's demand to different weeks.
A38: "What if a project takes longer?" | B38: Push the End Date further out. The same total hours get spread over more weeks, so weekly demand drops — but it stays on the heatmap longer.
A39: "What if we change how much BA time a project needs?" | B39: Go to RM_Assumptions → Role Effort by Phase (rows 21-28) → adjust the BA row. This changes how much BA demand every project generates during each phase.
A40: "What if we shift more time to admin?" | B40: Go to RM_Assumptions → Time Allocation (rows 7-9) → increase Admin %, decrease Project %. Everyone's available project hours shrink, so utilization goes up across the board.
A41: Reset everything | B41: Set all Headcount Adjusters back to 0. The project dates will revert to Portfolio defaults on their own (they pull from Portfolio when not overridden).
A44: READING THE HEATMAP COLORS
A45: 🟢 Green (under 80%) | B45: This role has capacity. No action needed.
A46: 🟡 Yellow (80-99%) | B46: At risk. A short burst of yellow (1-2 weeks) is OK — people can push through. But sustained yellow over 3+ weeks means you're running tight and any surprise will tip into red.
A47: 🔴 Red (100% or higher) | B47: Over capacity. This role physically can't deliver everything assigned to them. Something has to give: hire more, delay a project, or reassign work. The higher the %, the worse it is (183% means you'd need almost 2x the people).
A48: All zeros (0%) | B48: Either no projects are active that week, or no projects need that role. Check if project dates are set correctly in the timeline section.
A51: IMPORTANT NOTES
A52: Projects with no dates | B52: If a project in the Portfolio has no Start/End date, the heatmap defaults it to starting today with a 12-week duration. Once real dates are added to the Portfolio, it picks them up automatically.
A53: Completed/Postponed projects | B53: These are automatically excluded from all demand calculations. You don't need to remove them.
A54: Phase totals over 100% | B54: In RM_Assumptions, the Phase Total row may show >100%. This is correct — it means multiple roles work on the same phase. It's not a distribution (doesn't need to sum to 100%), it's effort intensity per role.
A55: Headcount vs. Team Roster | B55: Base headcount in the heatmap comes from Team Roster via RM_Assumptions. The Adjuster in the heatmap is a temporary "what if" — it doesn't change the actual roster.
A56: Don't edit gray cells | B56: Gray cells contain formulas. If you overwrite them, the model breaks. Only edit blue cells.
...

Sheet AI_Agent_Spec
A1: ETE IT PMO — AI Resource Planning Agent: Technical Specification
A2: Phase 1 MVP — Stateful AI agent for resource optimization, portfolio analysis, and decision support.
A4: 1. PROJECT OVERVIEW
A5: Project Name | B5: ETE IT PMO AI Resource Planning Agent
A6: Version | B6: Phase 1 MVP
A7: Purpose | B7: Build a persistent AI agent that reads the ETE IT PMO Excel workbook, understands the project portfolio and team capacity, runs constraint-based optimization for resource scheduling, and provides natural language recommendations via a chat interface. Excel remains the source of truth for data entry and executive/board reporting.
A8: Problem Statement | B8: The PMO team manually manages 40+ projects across 23 resources using Excel. Determining optimal project schedules, identifying resource bottlenecks, and running what-if scenarios requires navigating 6+ interconnected sheets with complex formulas. The team needs an intelligent layer that can answer capacity questions, flag risks, and recommend optimal schedules — while keeping Excel as the foundation.
