Workbook

Sheet Dashboard
A1: ETE IT PMO — Resource & Project Management Dashboard
B3: TEAM SIZE | E3: WEEKLY CAPACITY | H3: TEAM UTILIZATION | L3: starting / available time | O3: use 10/10/80
B4: =COUNTA('Team Roster'!A4:A26) -> 23 | E4: ='Team Roster'!K27 -> 438.74 | H4: =I15 -> 0.105158 | L4: allocation of available time: allocate 10% allocation for admin, 15% for break/fix, 75% for projects - 40 hour week
B5: Total resources | E5: Net project hrs/wk | H5: Across active weeks
L6: this gives us our model of resource availability; meetings should be focused on the project and project plan
B7: RESOURCE CAPACITY OVERVIEW
B8: Team | C8: Headcount | D8: Weekly Hrs | E8: Support Reserve | F8: Net Capacity | G8: Avg Allocated | H8: Available | I8: Utilization | L8: for ba's / sdlc: 75% of effort on a project (of the 10%) is in discovery and planning
B9: Synnergie (ERP) | C9: =COUNTIF('Team Roster'!$C$4:$C$26,"ERP") -> 8 | D9: =SUMIF('Team Roster'!$C$4:$C$26,"ERP",'Team Roster'!$G$4:$G$26) -> 280 | E9: =SUMIF('Team Roster'!$C$4:$C$26,"ERP",'Team Roster'!$J$4:$J$26) -> 105 | F9: =SUMIF('Team Roster'!$C$4:$C$26,"ERP",'Team Roster'!$K$4:$K$26) -> 175 | G9: {=IFERROR(SUMPRODUCT(('Capacity Heatmap'!$C$5:$C$26="Synnergie")*(MMULT(IF('Capacity Heatmap'!$E$5:$AD$26>0,'Capacity Heatmap'!$E$5:$AD$26,0),_xlfn.SEQUENCE(26,1,1,0))/IF(MMULT(IF('Capacity Heatmap'!$E$5:$AD$26>0,1,0),_xlfn.SEQUENCE(26,1,1,0))>0,MMULT(IF('Capacity Heatmap'!$E$5:$AD$26>0,1,0),_xlfn.SEQUENCE(26,1,1,0)),1))*'Capacity Heatmap'!$D$5:$D$26),0)} -> 13.5 | H9: =F9-G9 -> 161.5 | I9: =IF(F9>0,G9/F9,0) -> 0.077142857 | L9: rest of their time is the other / remainder
B10: Systems Applications | C10: =COUNTIF('Team Roster'!$C$4:$C$26,"Systems Applications") -> 4 | D10: =SUMIF('Team Roster'!$C$4:$C$26,"Systems Applications",'Team Roster'!$G$4:$G$26) -> 100 | E10: =SUMIF('Team Roster'!$C$4:$C$26,"Systems Applications",'Team Roster'!$J$4:$J$26) -> 31.25 | F10: =SUMIF('Team Roster'!$C$4:$C$26,"Systems Applications",'Team Roster'!$K$4:$K$26) -> 68.75 | G10: {=IFERROR(SUMPRODUCT(('Capacity Heatmap'!$C$5:$C$26="Systems Applications")*(MMULT(IF('Capacity Heatmap'!$E$5:$AD$26>0,'Capacity Heatmap'!$E$5:$AD$26,0),_xlfn.SEQUENCE(26,1,1,0))/IF(MMULT(IF('Capacity Heatmap'!$E$5:$AD$26>0,1,0),_xlfn.SEQUENCE(26,1,1,0))>0,MMULT(IF('Capacity Heatmap'!$E$5:$AD$26>0,1,0),_xlfn.SEQUENCE(26,1,1,0)),1))*'Capacity Heatmap'!$D$5:$D$26),0)} -> 20.869565 | H10: =F10-G10 -> 47.880435 | I10: =IF(F10>0,G10/F10,0) -> 0.30355731 | L10: technical side (discovery/ planning) - 5-%, design is 50-75%, build is 75%-80%
B11: Business Analysts | C11: =COUNTIF('Team Roster'!$C$4:$C$26,"Business Analysts") -> 4 | D11: =SUMIF('Team Roster'!$C$4:$C$26,"Business Analysts",'Team Roster'!$G$4:$G$26) -> 145 | E11: =SUMIF('Team Roster'!$C$4:$C$26,"Business Analysts",'Team Roster'!$J$4:$J$26) -> 66 | F11: =SUMIF('Team Roster'!$C$4:$C$26,"Business Analysts",'Team Roster'!$K$4:$K$26) -> 79 | G11: {=IFERROR(SUMPRODUCT(('Capacity Heatmap'!$C$5:$C$26="Business Analysts")*(MMULT(IF('Capacity Heatmap'!$E$5:$AD$26>0,'Capacity Heatmap'!$E$5:$AD$26,0),_xlfn.SEQUENCE(26,1,1,0))/IF(MMULT(IF('Capacity Heatmap'!$E$5:$AD$26>0,1,0),_xlfn.SEQUENCE(26,1,1,0))>0,MMULT(IF('Capacity Heatmap'!$E$5:$AD$26>0,1,0),_xlfn.SEQUENCE(26,1,1,0)),1))*'Capacity Heatmap'!$D$5:$D$26),0)} -> 8.7674572 | H11: =F11-G11 -> 70.232543 | I11: =IF(F11>0,G11/F11,0) -> 0.11098047
B12: Infrastructure | C12: =COUNTIF('Team Roster'!$C$4:$C$26,"Infrastructure") -> 3 | D12: =SUMIF('Team Roster'!$C$4:$C$26,"Infrastructure",'Team Roster'!$G$4:$G$26) -> 120 | E12: =SUMIF('Team Roster'!$C$4:$C$26,"Infrastructure",'Team Roster'!$J$4:$J$26) -> 72 | F12: =SUMIF('Team Roster'!$C$4:$C$26,"Infrastructure",'Team Roster'!$K$4:$K$26) -> 48 | G12: {=IFERROR(SUMPRODUCT(('Capacity Heatmap'!$C$5:$C$26="Infrastructure")*(MMULT(IF('Capacity Heatmap'!$E$5:$AD$26>0,'Capacity Heatmap'!$E$5:$AD$26,0),_xlfn.SEQUENCE(26,1,1,0))/IF(MMULT(IF('Capacity Heatmap'!$E$5:$AD$26>0,1,0),_xlfn.SEQUENCE(26,1,1,0))>0,MMULT(IF('Capacity Heatmap'!$E$5:$AD$26>0,1,0),_xlfn.SEQUENCE(26,1,1,0)),1))*'Capacity Heatmap'!$D$5:$D$26),0)} -> 0 | H12: =F12-G12 -> 48 | I12: =IF(F12>0,G12/F12,0) -> 0 | L12: no more than 3 projects per person at a time
B13: WMS | C13: =COUNTIF('Team Roster'!$C$4:$C$26,"WMS") -> 1 | D13: =SUMIF('Team Roster'!$C$4:$C$26,"WMS",'Team Roster'!$G$4:$G$26) -> 35 | E13: =SUMIF('Team Roster'!$C$4:$C$26,"WMS",'Team Roster'!$J$4:$J$26) -> 21 | F13: =SUMIF('Team Roster'!$C$4:$C$26,"WMS",'Team Roster'!$K$4:$K$26) -> 14 | G13: {=IFERROR(SUMPRODUCT(('Capacity Heatmap'!$C$5:$C$26="WMS")*(MMULT(IF('Capacity Heatmap'!$E$5:$AD$26>0,'Capacity Heatmap'!$E$5:$AD$26,0),_xlfn.SEQUENCE(26,1,1,0))/IF(MMULT(IF('Capacity Heatmap'!$E$5:$AD$26>0,1,0),_xlfn.SEQUENCE(26,1,1,0))>0,MMULT(IF('Capacity Heatmap'!$E$5:$AD$26>0,1,0),_xlfn.SEQUENCE(26,1,1,0)),1))*'Capacity Heatmap'!$D$5:$D$26),0)} -> 0 | H13: =F13-G13 -> 14 | I13: =IF(F13>0,G13/F13,0) -> 0
B14: PMO | C14: =COUNTIF('Team Roster'!$C$4:$C$26,"PMO") -> 3 | D14: =SUMIF('Team Roster'!$C$4:$C$26,"PMO",'Team Roster'!$G$4:$G$26) -> 102 | E14: =SUMIF('Team Roster'!$C$4:$C$26,"PMO",'Team Roster'!$J$4:$J$26) -> 48.01 | F14: =SUMIF('Team Roster'!$C$4:$C$26,"PMO",'Team Roster'!$K$4:$K$26) -> 53.99 | G14: {=IFERROR(SUMPRODUCT(('Capacity Heatmap'!$C$5:$C$26="PMO")*(MMULT(IF('Capacity Heatmap'!$E$5:$AD$26>0,'Capacity Heatmap'!$E$5:$AD$26,0),_xlfn.SEQUENCE(26,1,1,0))/IF(MMULT(IF('Capacity Heatmap'!$E$5:$AD$26>0,1,0),_xlfn.SEQUENCE(26,1,1,0))>0,MMULT(IF('Capacity Heatmap'!$E$5:$AD$26>0,1,0),_xlfn.SEQUENCE(26,1,1,0)),1))*'Capacity Heatmap'!$D$5:$D$26),0)} -> 3 | H14: =F14-G14 -> 50.99 | I14: =IF(F14>0,G14/F14,0) -> 0.055565846 | L14: once developers are done, then ba's go from 10-15% to 25%-30%
B15: TOTAL | C15: =SUM(C9:C14) -> 23 | D15: =SUM(D9:D14) -> 782 | E15: =SUM(E9:E14) -> 343.26 | F15: =SUM(F9:F14) -> 438.74 | G15: =SUM(G9:G14) -> 46.137022 | H15: =SUM(H9:H14) -> 392.60298 | I15: =IF(F15>0,G15/F15,0) -> 0.105158
L16: need multiple dimensions in the model for how we visualize the projects - some might be businer in some phases
B17: PROJECT STATUS SUMMARY
B18: Category | C18: Total | D18: Complete | E18: In Progress | F18: Not Started | G18: Needs Help | H18: Needs Spec | I18: Postponed | J18: % Complete | L18: 32 hours, divide by 2, 16 hours free for something else - gives availability of who's red and and not; assign people to rosters
B19: Project Portfolio | C19: =COUNTA('Project Portfolio'!A4:A42)-COUNTBLANK('Project Portfolio'!A4:A42) -> 37 | D19: =COUNTIF('Project Portfolio'!F4:F42,"✅ COMPLETE") -> 16 | E19: =COUNTIF('Project Portfolio'!F4:F42,"🟢 ON TRACK")+COUNTIF('Project Portfolio'!F4:F42,"🔵 ON HOLD") -> 4 | F19: =COUNTIF('Project Portfolio'!F4:F42,"⚪ NOT STARTED") -> 2 | G19: =COUNTIF('Project Portfolio'!F4:F42,"🟡 AT RISK")+COUNTIF('Project Portfolio'!F4:F42,"🔴 NEEDS ATTENTION") -> 0 | H19: =COUNTIF('Project Portfolio'!F4:F42,"📋 NEEDS TECHNICAL SPEC")+COUNTIF('Project Portfolio'!F4:F42,"📋 NEEDS FUNCTIONAL SPEC") -> 7 | I19: =COUNTIF('Project Portfolio'!F4:F42,"⏸️ POSTPONED")+COUNTIF('Project Portfolio'!F4:F42,"⏳ AWAITING APPROVAL") -> 9 | J19: =IF(C19>0,D19/C19,0) -> 0.43243243
L20: can be assigned to more than 2-3 projeects start/ end at different times
L21: identify how much work is required per resource type per week; maybe as an ex: 300 per ba: have more demand than supply
G22: must have staggerred start dates based on resource capacity adn avail | L22: heatmap to change when we add an additional person b/c more resources
G23: dates, groups, resource capacity, etc.. amount of work does not change | L23: do we have all the right people or not
G24: but as we move dates it should change heatmap b/c of availability

Sheet Team Roster
A1: ETE IT PMO — Team Roster & Capacity
A3: Resource | B3: Role | C3: Team | D3: Vendor | E3: Resource Classification | F3: Rate/Hour | G3: Weekly Hrs Available | H3: Support Reserve % | I3: Project Capacity % | J3: Support Reserve (hrs/wk) | K3: Project Capacity (hrs/wk)
A4: Ajay Kumar | B4: Functional | C4: ERP | D4: Synnergie | E4: MSA | F4: 65 | G4: 35 | H4: 0.4 | I4: =1-H4 -> 0.6 | J4: =G4*H4 -> 14 | K4: =G4*I4 -> 21
A5: Ravindra Reddy | B5: Technical | C5: ERP | D5: Synnergie | E5: MSA | F5: 65 | G5: 35 | H5: 0.4 | I5: =1-H5 -> 0.6 | J5: =G5*H5 -> 14 | K5: =G5*I5 -> 21
A6: Vishnu Premen | B6: Technical | C6: ERP | D6: Synnergie | E6: =IF(D6="Synnergie","T&M",IF(D6="Watermark","MSA",IF(D6="ETE","Internal",""))) -> T&M | F6: 65 | G6: 35 | H6: 0.4 | I6: =1-H6 -> 0.6 | J6: =G6*H6 -> 14 | K6: =G6*I6 -> 21
A7: Deepak Gudwani | B7: Functional | C7: ERP | D7: Synnergie | E7: =IF(D7="Synnergie","T&M",IF(D7="Watermark","MSA",IF(D7="ETE","Internal",""))) -> T&M | F7: 65 | G7: 35 | H7: 0.4 | I7: =1-H7 -> 0.6 | J7: =G7*H7 -> 14 | K7: =G7*I7 -> 21
A8: Sangamesh Koti | B8: Technical | C8: ERP | D8: Synnergie | E8: T&M | F8: 65 | G8: 35 | H8: 0 | I8: =1-H8 -> 1 | J8: =G8*H8 -> 0 | K8: =G8*I8 -> 35
A9: Bhavya Reddy | B9: Technical | C9: ERP | D9: Synnergie | E9: =IF(D9="Synnergie","T&M",IF(D9="Watermark","MSA",IF(D9="ETE","Internal",""))) -> T&M | F9: 65 | G9: 35 | H9: 0 | I9: =1-H9 -> 1 | J9: =G9*H9 -> 0 | K9: =G9*I9 -> 35
A10: Sarath Yeturu | B10: Technical | C10: ERP | D10: Synnergie | E10: MSA | F10: 65 | G10: 35 | H10: 0.6 | I10: =1-H10 -> 0.4 | J10: =G10*H10 -> 21 | K10: =G10*I10 -> 14
A11: Vinod Bollepally | B11: DBA | C11: ERP | D11: Synnergie | E11: MSA | F11: 65 | G11: 35 | H11: 0.8 | I11: =1-H11 -> 0.2 | J11: =G11*H11 -> 28 | K11: =G11*I11 -> 7
A12: Jim Young | B12: Business Analyst | C12: Business Analysts | D12: ETE | E12: =IF(D12="Synnergie","T&M",IF(D12="Watermark","MSA",IF(D12="ETE","Internal",""))) -> Internal | F12: 65 | G12: 40 | H12: 0.6 | I12: =1-H12 -> 0.4 | J12: =G12*H12 -> 24 | K12: =G12*I12 -> 16
A13: Alex Young | B13: Developer | C13: Systems Applications | D13: ETE | E13: =IF(D13="Synnergie","T&M",IF(D13="Watermark","MSA",IF(D13="ETE","Internal",""))) -> Internal | F13: 65 | G13: 25 | H13: 0.5 | I13: =1-H13 -> 0.5 | J13: =G13*H13 -> 12.5 | K13: =G13*I13 -> 12.5
A14: Nick Smith | B14: Developer | C14: Systems Applications | D14: ETE | E14: =IF(D14="Synnergie","T&M",IF(D14="Watermark","MSA",IF(D14="ETE","Internal",""))) -> Internal | F14: 65 | G14: 25 | H14: 0.4 | I14: =1-H14 -> 0.6 | J14: =G14*H14 -> 10 | K14: =G14*I14 -> 15
A15: Colin Olson | B15: Developer | C15: Systems Applications | D15: ETE | E15: =IF(D15="Synnergie","T&M",IF(D15="Watermark","MSA",IF(D15="ETE","Internal",""))) -> Internal | F15: 65 | G15: 25 | H15: 0.1 | I15: =1-H15 -> 0.9 | J15: =G15*H15 -> 2.5 | K15: =G15*I15 -> 22.5
A16: Jonathon Gonzalez | B16: Developer | C16: Systems Applications | D16: ETE | E16: =IF(D16="Synnergie","T&M",IF(D16="Watermark","MSA",IF(D16="ETE","Internal",""))) -> Internal | F16: 65 | G16: 25 | H16: 0.25 | I16: =1-H16 -> 0.75 | J16: =G16*H16 -> 6.25 | K16: =G16*I16 -> 18.75
A17: Audrey Debaere | B17: Business Analyst | C17: Business Analysts | D17: ETE | E17: =IF(D17="Synnergie","T&M",IF(D17="Watermark","MSA",IF(D17="ETE","Internal",""))) -> Internal | F17: 65 | G17: 35 | H17: 0.5 | I17: =1-H17 -> 0.5 | J17: =G17*H17 -> 17.5 | K17: =G17*I17 -> 17.5
A18: Cristian Varelas | B18: Business Analyst | C18: Business Analysts | D18: ETE | E18: =IF(D18="Synnergie","T&M",IF(D18="Watermark","MSA",IF(D18="ETE","Internal",""))) -> Internal | F18: 65 | G18: 35 | H18: 0.2 | I18: =1-H18 -> 0.8 | J18: =G18*H18 -> 7 | K18: =G18*I18 -> 28
A19: Ryan Picado | B19: Business Analyst | C19: Business Analysts | D19: ETE | E19: =IF(D19="Synnergie","T&M",IF(D19="Watermark","MSA",IF(D19="ETE","Internal",""))) -> Internal | F19: 65 | G19: 35 | H19: 0.5 | I19: =1-H19 -> 0.5 | J19: =G19*H19 -> 17.5 | K19: =G19*I19 -> 17.5
A20: Emily Fridley | B20: Project Manager | C20: PMO | D20: ETE | E20: =IF(D20="Synnergie","T&M",IF(D20="Watermark","MSA",IF(D20="ETE","Internal",""))) -> Internal | F20: 65 | G20: 35 | H20: 0.5 | I20: =1-H20 -> 0.5 | J20: =G20*H20 -> 17.5 | K20: =G20*I20 -> 17.5
A21: Brett Anderson | B21: Project Manager | C21: PMO | D21: ETE | E21: =IF(D21="Synnergie","T&M",IF(D21="Watermark","MSA",IF(D21="ETE","Internal",""))) -> Internal | F21: 65 | G21: 35 | H21: 0.25 | I21: =1-H21 -> 0.75 | J21: =G21*H21 -> 8.75 | K21: =G21*I21 -> 26.25
A22: Bettina Kotico | B22: Project Manager | C22: PMO | D22: Kayana | E22: T&M | F22: 65 | G22: 32 | H22: 0.68 | I22: =1-H22 -> 0.32 | J22: =G22*H22 -> 21.76 | K22: =G22*I22 -> 10.24
A23: Donna Wiedemeier | B23: WMS Consultant | C23: WMS | D23: Watermark | E23: T&M | F23: 65 | G23: 35 | H23: 0.6 | I23: =1-H23 -> 0.4 | J23: =G23*H23 -> 21 | K23: =G23*I23 -> 14
A24: Justin Senour | B24: Infrastructure | C24: Infrastructure | D24: ETE | E24: =IF(D24="Synnergie","T&M",IF(D24="Watermark","MSA",IF(D24="ETE","Internal",""))) -> Internal | F24: 65 | G24: 40 | H24: 0.6 | I24: =1-H24 -> 0.4 | J24: =G24*H24 -> 24 | K24: =G24*I24 -> 16
A25: Michael House | B25: Infrastructure | C25: Infrastructure | D25: ETE | E25: =IF(D25="Synnergie","T&M",IF(D25="Watermark","MSA",IF(D25="ETE","Internal",""))) -> Internal | F25: 65 | G25: 40 | H25: 0.6 | I25: =1-H25 -> 0.4 | J25: =G25*H25 -> 24 | K25: =G25*I25 -> 16
A26: Andrew Shaefer | B26: Infrastructure | C26: Infrastructure | D26: ETE | E26: =IF(D26="Synnergie","T&M",IF(D26="Watermark","MSA",IF(D26="ETE","Internal",""))) -> Internal | F26: 65 | G26: 40 | H26: 0.6 | I26: =1-H26 -> 0.4 | J26: =G26*H26 -> 24 | K26: =G26*I26 -> 16
A27: TOTALS | G27: =SUM(G4:G26) -> 782 | H27: =IF(G27>0,J27/G27,0) -> 0.43895141 | I27: =IF(G27>0,K27/G27,0) -> 0.56104859 | J27: =SUM(J4:J26) -> 343.26 | K27: =SUM(K4:K26) -> 438.74

Sheet Project Portfolio
A1: ETE IT PMO — Project Portfolio
A3: ID | B3: Project Name | C3: Type | D3: Business Portfolio | E3: Sponsor/Leader | F3: Project Health | G3: % Complete | H3: Priority | I3: Start Date | J3: Est. End Date | K3: Actual/Updated End | L3: Team | M3: PM | N3: BA | O3: Functional | P3: Technical | Q3: T-Shirt Size | R3: Est. Hours | S3: Est. Cost Range | T3: BA % | U3: Functional % | V3: Technical % | W3: Developer % | X3: Infrastructure % | Y3: DBA % | Z3: PM % | AA3: WMS % | AB3: Notes | AC3: Sort Order
A4: ETE-83 | B4: Customer Master Data Cleanup | C4: Key Initiative | D4: Sales & Distribution | E4: Tom Vierling | F4: 📋 NEEDS TECHNICAL SPEC | G4: 0.15 | H4: High | I4: 45944 | J4: 46174 | L4: Systems Applications | N4: Jim Young | Q4: XXL: > 640 Hours | R4: 1480 | S4: =$R4*65 -> 96200 | T4: 0.1 | AB4: Completed Q1 | AC4: =IF(OR(ISNUMBER(SEARCH("POSTPONED",$F4)),ISNUMBER(SEARCH("NOT APPROVED",$F4))),2,IF(ISNUMBER(SEARCH("COMPLETE",$F4)),3,1)) -> 1
A5: ETE-48 | B5: System Connection Syteline-VKS | C5: Key Initiative | D5: Engineering | E5: Ray Trumble | F5: 🟢 ON TRACK | G5: 0.1 | H5: High | I5: 46068 | J5: 46203 | L5: Synnergie | M5: Emily Fridley | Q5: L: 160-320 Hours | R5: 240 | S5: =$R5*65 -> 15600 | T5: 0.1 | Z5: 0.25 | AC5: =IF(OR(ISNUMBER(SEARCH("POSTPONED",$F5)),ISNUMBER(SEARCH("NOT APPROVED",$F5))),2,IF(ISNUMBER(SEARCH("COMPLETE",$F5)),3,1)) -> 1
A6: ETE-68 | B6: Catalog API Rust2Python | C6: Key Initiative | D6: Information Technology | E6: Jim Koscielniak | F6: 🟢 ON TRACK | G6: 0.13 | H6: High | I6: 45978 | J6: 46136 | L6: Systems Applications | N6: Cristian Varelas | P6: Colin Olson | Q6: XXL: > 640 Hours | R6: 640 | S6: =$R6*65 -> 41600 | T6: 0.1 | W6: 0.75 | AC6: =IF(OR(ISNUMBER(SEARCH("POSTPONED",$F6)),ISNUMBER(SEARCH("NOT APPROVED",$F6))),2,IF(ISNUMBER(SEARCH("COMPLETE",$F6)),3,1)) -> 1
A7: ETE-43 | B7: Data Security - Microsoft Purview | C7: Key Initiative | D7: Information Technology | E7: Jim Koscielniak | F7: 🟢 ON TRACK | G7: 0 | H7: High | I7: 46055 | J7: 46203 | L7: Infrastructure | R7: 0 | S7: =$R7*65 -> 0 | T7: 0.1 | AC7: =IF(OR(ISNUMBER(SEARCH("POSTPONED",$F7)),ISNUMBER(SEARCH("NOT APPROVED",$F7))),2,IF(ISNUMBER(SEARCH("COMPLETE",$F7)),3,1)) -> 1
A8: ETE-19 | B8: Changes to AR Aging Report | C8: Enhancement | D8: Finance | E8: Tom Newell | F8: 🟢 ON TRACK | G8: 0 | H8: High | I8: 46076 | J8: 46129 | L8: Synnergie | N8: Audrey Debaere | O8: Ajay Kumar | P8: Bhavya Reddy | Q8: M: 80-160 Hours | R8: 120 | S8: =$R8*65 -> 7800 | T8: 0.1 | U8: 0.25 | V8: 0.65 | AC8: =IF(OR(ISNUMBER(SEARCH("POSTPONED",$F8)),ISNUMBER(SEARCH("NOT APPROVED",$F8))),2,IF(ISNUMBER(SEARCH("COMPLETE",$F8)),3,1)) -> 1
A9: ETE-49 | B9: Marketing: STE Rewards Tier | C9: Enhancement | D9: Sales & Distribution | E9: Tom Vierling | F9: 📋 NEEDS TECHNICAL SPEC | G9: 0 | H9: Medium | L9: Systems Applications | N9: Cristian Varelas | Q9: L: 160-320 Hours | R9: 240 | S9: =$R9*65 -> 15600 | T9: 0.1 | U9: 0 | V9: 0 | W9: 0.75 | X9: 0 | Y9: 0 | Z9: 0 | AA9: 0 | AC9: =IF(OR(ISNUMBER(SEARCH("POSTPONED",$F9)),ISNUMBER(SEARCH("NOT APPROVED",$F9))),2,IF(ISNUMBER(SEARCH("COMPLETE",$F9)),3,1)) -> 1
A10: ETE-7 | B10: Outsourced Unit Core Accounting | C10: Enhancement | D10: Finance | E10: Tom Newell | F10: 📋 NEEDS FUNCTIONAL SPEC | G10: 0 | H10: Medium | L10: Synnergie | N10: Audrey Debaere | Q10: XXL: > 640 Hours | R10: 640 | S10: =$R10*65 -> 41600 | T10: 0.1 | U10: 0.25 | V10: 0.65 | W10: 0 | X10: 0 | Y10: 0 | Z10: 0 | AA10: 0 | AB10: 8-9 month project | AC10: =IF(OR(ISNUMBER(SEARCH("POSTPONED",$F10)),ISNUMBER(SEARCH("NOT APPROVED",$F10))),2,IF(ISNUMBER(SEARCH("COMPLETE",$F10)),3,1)) -> 1
A11: ETE-52 | B11: SWIMS/Syteline Reporting | C11: Enhancement | D11: Supply Chain | E11: Jon Besherse | F11: 📋 NEEDS TECHNICAL SPEC | G11: 0 | H11: Medium | L11: Systems Applications | N11: Ryan Picado | Q11: S: < 80 Hours | R11: 40 | S11: =$R11*65 -> 2600 | T11: 0.1 | U11: 0 | V11: 0 | W11: 0.75 | X11: 0 | Y11: 0 | Z11: 0 | AA11: 0 | AC11: =IF(OR(ISNUMBER(SEARCH("POSTPONED",$F11)),ISNUMBER(SEARCH("NOT APPROVED",$F11))),2,IF(ISNUMBER(SEARCH("COMPLETE",$F11)),3,1)) -> 1
A12: ETE-16 | B12: Partial Pay w/ CC from WMERP | C12: Enhancement | D12: Finance | E12: Tom Newell | F12: ⚪ NOT STARTED | G12: 0 | H12: Medium | L12: Synnergie | Q12: M: 80-160 Hours | R12: 120 | S12: =$R12*65 -> 7800 | T12: 0.1 | U12: 0.25 | V12: 0.65 | W12: 0 | X12: 0 | Y12: 0 | Z12: 0 | AA12: 0 | AC12: =IF(OR(ISNUMBER(SEARCH("POSTPONED",$F12)),ISNUMBER(SEARCH("NOT APPROVED",$F12))),2,IF(ISNUMBER(SEARCH("COMPLETE",$F12)),3,1)) -> 1
A13: ETE-37 | B13: Magic Search in BuyETE | C13: Enhancement | D13: Sales & Distribution | E13: Tom Vierling | F13: 📋 NEEDS TECHNICAL SPEC | G13: 0 | H13: Highest | L13: Systems Applications | N13: Cristian Varelas | Q13: S: < 80 Hours | R13: 40 | S13: =$R13*65 -> 2600 | T13: 0.1 | U13: 0.25 | V13: 0 | W13: 0.65 | X13: 0 | Y13: 0 | Z13: 0 | AA13: 0 | AC13: =IF(OR(ISNUMBER(SEARCH("POSTPONED",$F13)),ISNUMBER(SEARCH("NOT APPROVED",$F13))),2,IF(ISNUMBER(SEARCH("COMPLETE",$F13)),3,1)) -> 1
A14: ETE-97 | B14: Standard Order Process Notifications | C14: Enhancement | D14: Sales & Distribution | E14: Tom Vierling | F14: ⚪ NOT STARTED | G14: 0 | H14: Highest | L14: Systems Applications | R14: 200 | S14: =$R14*65 -> 13000 | T14: 0.1 | U14: 0 | V14: 0 | W14: 0.75 | X14: 0 | Y14: 0 | Z14: 0 | AA14: 0 | AC14: =IF(OR(ISNUMBER(SEARCH("POSTPONED",$F14)),ISNUMBER(SEARCH("NOT APPROVED",$F14))),2,IF(ISNUMBER(SEARCH("COMPLETE",$F14)),3,1)) -> 1
A15: ETE-100 | B15: ATSG Expired Members Self-Payment | C15: Enhancement | D15: Sales & Distribution | E15: Tom Vierling | F15: 📋 NEEDS FUNCTIONAL SPEC | G15: 0 | H15: Medium | L15: Systems Applications | R15: 200 | S15: =$R15*65 -> 13000 | T15: 0.1 | U15: 0 | V15: 0 | W15: 0.75 | X15: 0 | Y15: 0 | Z15: 0 | AA15: 0 | AC15: =IF(OR(ISNUMBER(SEARCH("POSTPONED",$F15)),ISNUMBER(SEARCH("NOT APPROVED",$F15))),2,IF(ISNUMBER(SEARCH("COMPLETE",$F15)),3,1)) -> 1
A16: ETE-124 | B16: Clean Up Return Loads | C16: Enhancement | D16: Finance | E16: Tom Newell | F16: 📋 NEEDS TECHNICAL SPEC | G16: 0 | H16: Highest | L16: Synnergie | R16: 200 | S16: =$R16*65 -> 13000 | T16: 0.1 | U16: 0.25 | V16: 0.75 | W16: 0 | X16: 0 | Y16: 0 | Z16: 0 | AA16: 0 | AC16: =IF(OR(ISNUMBER(SEARCH("POSTPONED",$F16)),ISNUMBER(SEARCH("NOT APPROVED",$F16))),2,IF(ISNUMBER(SEARCH("COMPLETE",$F16)),3,1)) -> 1
AC17: =IF(OR(ISNUMBER(SEARCH("POSTPONED",$F17)),ISNUMBER(SEARCH("NOT APPROVED",$F17))),2,IF(ISNUMBER(SEARCH("COMPLETE",$F17)),3,1)) -> 1
A18: ETE-58 | B18: Transfer Order Moved Items to Transit Location | C18: Enhancement | D18: Finance | E18: Jim Young | F18: ⏸️ POSTPONED | G18: 0 | AC18: =IF(OR(ISNUMBER(SEARCH("POSTPONED",$F18)),ISNUMBER(SEARCH("NOT APPROVED",$F18))),2,IF(ISNUMBER(SEARCH("COMPLETE",$F18)),3,1)) -> 2
A19: ETE-51 | B19: RMA Credit Memo on Ghost Check-In | C19: Enhancement | D19: Finance | E19: Tom Newell | F19: ⏸️ POSTPONED | G19: 0 | AC19: =IF(OR(ISNUMBER(SEARCH("POSTPONED",$F19)),ISNUMBER(SEARCH("NOT APPROVED",$F19))),2,IF(ISNUMBER(SEARCH("COMPLETE",$F19)),3,1)) -> 2
A20: ETE-59 | B20: Reconcile BridgePay CC Transactions | C20: Enhancement | D20: Finance | E20: Tom Newell | F20: ⏸️ POSTPONED | G20: 0 | AC20: =IF(OR(ISNUMBER(SEARCH("POSTPONED",$F20)),ISNUMBER(SEARCH("NOT APPROVED",$F20))),2,IF(ISNUMBER(SEARCH("COMPLETE",$F20)),3,1)) -> 2
A21: ETE-60 | B21: EDI Payments Not Posting on Background | C21: Enhancement | D21: Finance | E21: Tom Newell | F21: ⏸️ POSTPONED | G21: 0 | AC21: =IF(OR(ISNUMBER(SEARCH("POSTPONED",$F21)),ISNUMBER(SEARCH("NOT APPROVED",$F21))),2,IF(ISNUMBER(SEARCH("COMPLETE",$F21)),3,1)) -> 2
A22: ETE-61 | B22: Accum Deposits Received Field | C22: Bug | D22: Finance | E22: Tom Newell | F22: ⏸️ POSTPONED | G22: 0 | AC22: =IF(OR(ISNUMBER(SEARCH("POSTPONED",$F22)),ISNUMBER(SEARCH("NOT APPROVED",$F22))),2,IF(ISNUMBER(SEARCH("COMPLETE",$F22)),3,1)) -> 2
A23: ETE-86 | B23: Allow TCM Core Receiving to Post | C23: Enhancement | D23: Engineering | E23: Ray Trumble | F23: ⏸️ POSTPONED | G23: 0 | AC23: =IF(OR(ISNUMBER(SEARCH("POSTPONED",$F23)),ISNUMBER(SEARCH("NOT APPROVED",$F23))),2,IF(ISNUMBER(SEARCH("COMPLETE",$F23)),3,1)) -> 2
A24: ETE-34 | B24: Salesforce BDR Application & Process Implementation | C24: Enhancement | D24: Sales & Distribution | E24: Tom Vierling | F24: ⏸️ POSTPONED | G24: 0 | AC24: =IF(OR(ISNUMBER(SEARCH("POSTPONED",$F24)),ISNUMBER(SEARCH("NOT APPROVED",$F24))),2,IF(ISNUMBER(SEARCH("COMPLETE",$F24)),3,1)) -> 2
A25: ETE-35 | B25: BuyETE Ability for Customers to Save Quotes | C25: Enhancement | D25: Sales & Distribution | E25: Tom Vierling | F25: ⏸️ POSTPONED | G25: 0 | AC25: =IF(OR(ISNUMBER(SEARCH("POSTPONED",$F25)),ISNUMBER(SEARCH("NOT APPROVED",$F25))),2,IF(ISNUMBER(SEARCH("COMPLETE",$F25)),3,1)) -> 2
A26: ETE-33 | B26: EDI 3PL Locations | C26: Enhancement | D26: Sales & Distribution | E26: Tom Vierling | F26: ⏸️ POSTPONED | G26: 0 | H26: High | L26: Systems Applications | N26: Jim Young | Q26: M: 80-160 Hours | R26: 120 | AC26: =IF(OR(ISNUMBER(SEARCH("POSTPONED",$F26)),ISNUMBER(SEARCH("NOT APPROVED",$F26))),2,IF(ISNUMBER(SEARCH("COMPLETE",$F26)),3,1)) -> 2
A27: ETE-67 | B27: Avalara Tax Issues | C27: Enhancement | D27: Finance | E27: Tom Newell | F27: ✅ COMPLETE | G27: 1 | H27: Highest | I27: 46057 | J27: 46080 | L27: Synnergie | N27: Audrey Debaere | O27: Deepak Gudwani | P27: Sangamesh Koti | Q27: M: 80-160 Hours | R27: 120 | S27: =$R27*65 -> 7800 | T27: 0.1 | U27: 0.25 | V27: 0.75 | AC27: =IF(OR(ISNUMBER(SEARCH("POSTPONED",$F27)),ISNUMBER(SEARCH("NOT APPROVED",$F27))),2,IF(ISNUMBER(SEARCH("COMPLETE",$F27)),3,1)) -> 3
A28: ETE-14 | B28: Installed Return RMA Type | C28: Enhancement | D28: Supply Chain | E28: Jon Besherse | F28: ✅ COMPLETE | G28: 1 | H28: Highest | I28: 46083 | J28: 46101 | L28: Synnergie | N28: Audrey Debaere | Q28: M: 80-160 Hours | R28: 120 | S28: =$R28*65 -> 7800 | T28: 0.1 | U28: 0.25 | V28: 0.65 | AC28: =IF(OR(ISNUMBER(SEARCH("POSTPONED",$F28)),ISNUMBER(SEARCH("NOT APPROVED",$F28))),2,IF(ISNUMBER(SEARCH("COMPLETE",$F28)),3,1)) -> 3
A29: ETE-70 | B29: Nutanix (Replace VMware) | C29: Key Initiative | D29: Information Technology | E29: Jim Koscielniak | F29: ✅ COMPLETE | G29: 1 | H29: Highest | I29: 45992 | J29: 46102 | L29: Infrastructure | P29: Michael House | R29: 120 | S29: =$R29*65 -> 7800 | T29: 0.1 | X29: 0.5 | AC29: =IF(OR(ISNUMBER(SEARCH("POSTPONED",$F29)),ISNUMBER(SEARCH("NOT APPROVED",$F29))),2,IF(ISNUMBER(SEARCH("COMPLETE",$F29)),3,1)) -> 3
A30: ETE-65 | B30: Rebuild Vendor Portal | C30: Enhancement | D30: Sales & Distribution | E30: Tom Vierling | F30: ✅ COMPLETE | G30: 1 | H30: High | I30: 45957 | J30: 46031 | K30: 46068 | L30: Systems Applications | N30: Jim Young | P30: Jonathon Gonzalez | Q30: S: < 80 Hours | R30: 60 | S30: 11895 | AC30: =IF(OR(ISNUMBER(SEARCH("POSTPONED",$F30)),ISNUMBER(SEARCH("NOT APPROVED",$F30))),2,IF(ISNUMBER(SEARCH("COMPLETE",$F30)),3,1)) -> 3
A31: ETE-69 | B31: Core Plan Optimization | C31: Key Initiative | D31: Supply Chain | E31: Jon Besherse | F31: ✅ COMPLETE | G31: 1 | H31: High | I31: 45973 | J31: 46045 | K31: 46045 | L31: Synnergie | N31: Audrey Debaere | P31: Ravindra Reddy | Q31: L: 160-320 Hours | R31: 360 | S31: 16120 | AC31: =IF(OR(ISNUMBER(SEARCH("POSTPONED",$F31)),ISNUMBER(SEARCH("NOT APPROVED",$F31))),2,IF(ISNUMBER(SEARCH("COMPLETE",$F31)),3,1)) -> 3
A32: ETE-31 | B32: Restocking Fees Added to RMA Credit Memo | C32: Enhancement | D32: Finance | E32: Tom Newell | F32: ✅ COMPLETE | G32: 1 | H32: High | I32: 45648 | J32: 46059 | K32: 46081 | L32: Synnergie | N32: Audrey Debaere | P32: Bhavya Reddy | Q32: L: 160-320 Hours | R32: 310 | S32: 1625 | AC32: =IF(OR(ISNUMBER(SEARCH("POSTPONED",$F32)),ISNUMBER(SEARCH("NOT APPROVED",$F32))),2,IF(ISNUMBER(SEARCH("COMPLETE",$F32)),3,1)) -> 3
A33: ETE-45 | B33: VB Bin Printer Integration | C33: Enhancement | D33: Engineering | E33: Ray Trumble | F33: ✅ COMPLETE | G33: 1 | H33: High | I33: 45950 | J33: 46073 | K33: 46073 | L33: Synnergie | N33: Cristian Varelas | P33: Sangamesh Koti | Q33: M: 80-160 Hours | R33: 160 | S33: 260 | AC33: =IF(OR(ISNUMBER(SEARCH("POSTPONED",$F33)),ISNUMBER(SEARCH("NOT APPROVED",$F33))),2,IF(ISNUMBER(SEARCH("COMPLETE",$F33)),3,1)) -> 3
A34: ETE-42 | B34: Gear Screen - Improved Production Oversight | C34: Key Initiative | D34: Production | E34: Ari Rosengarten | F34: ✅ COMPLETE | G34: 1 | H34: High | I34: 46034 | J34: 46058 | K34: 46081 | L34: Synnergie | N34: Cristian Varelas | P34: Vishnu Premen | Q34: M: 80-160 Hours | R34: 120 | AB34: NAPA not ready | AC34: =IF(OR(ISNUMBER(SEARCH("POSTPONED",$F34)),ISNUMBER(SEARCH("NOT APPROVED",$F34))),2,IF(ISNUMBER(SEARCH("COMPLETE",$F34)),3,1)) -> 3
A35: ETE-72 | B35: Fortigate ZTNA - EMS Setup | C35: Key Initiative | D35: Information Technology | E35: Jim Koscielniak | F35: ✅ COMPLETE | G35: 1 | H35: High | I35: 46003 | J35: 46022 | K35: 46080 | L35: Infrastructure | P35: Justin Senour | R35: 0 | AC35: =IF(OR(ISNUMBER(SEARCH("POSTPONED",$F35)),ISNUMBER(SEARCH("NOT APPROVED",$F35))),2,IF(ISNUMBER(SEARCH("COMPLETE",$F35)),3,1)) -> 3
A36: ETE-71 | B36: One Drive Migration | C36: Key Initiative | D36: Information Technology | E36: Jim Koscielniak | F36: ✅ COMPLETE | G36: 1 | H36: High | I36: 46013 | J36: 46059 | K36: 46068 | L36: Infrastructure | P36: Michael House | R36: 0 | AC36: =IF(OR(ISNUMBER(SEARCH("POSTPONED",$F36)),ISNUMBER(SEARCH("NOT APPROVED",$F36))),2,IF(ISNUMBER(SEARCH("COMPLETE",$F36)),3,1)) -> 3
A37: ETE-87 | B37: Production Dashboard | C37: Enhancement | D37: Production | E37: Ari Rosengarten | F37: ✅ COMPLETE | G37: 1 | H37: High | L37: Systems Applications | Q37: S: < 80 Hours | R37: 40 | AC37: =IF(OR(ISNUMBER(SEARCH("POSTPONED",$F37)),ISNUMBER(SEARCH("NOT APPROVED",$F37))),2,IF(ISNUMBER(SEARCH("COMPLETE",$F37)),3,1)) -> 3
A38: ETE-88 | B38: Return Load Phase 2 | C38: Key Initiative | D38: Finance | E38: Tom Newell | F38: ✅ COMPLETE | G38: 1 | H38: High | I38: 45957 | J38: 46020 | K38: 46031 | L38: Synnergie | N38: Audrey Debaere | P38: Sangamesh Koti | R38: 320 | AC38: =IF(OR(ISNUMBER(SEARCH("POSTPONED",$F38)),ISNUMBER(SEARCH("NOT APPROVED",$F38))),2,IF(ISNUMBER(SEARCH("COMPLETE",$F38)),3,1)) -> 3
A39: ETE-73 | B39: Teal Parts Daily Inventory Feed | C39: Enhancement | D39: Sales & Distribution | E39: Tom Vierling | F39: ✅ COMPLETE | G39: 1 | H39: Highest | L39: Systems Applications | N39: Cristian Varelas | Q39: S: < 80 Hours | R39: 40 | AC39: =IF(OR(ISNUMBER(SEARCH("POSTPONED",$F39)),ISNUMBER(SEARCH("NOT APPROVED",$F39))),2,IF(ISNUMBER(SEARCH("COMPLETE",$F39)),3,1)) -> 3
A40: ETE-10 | B40: Upload Utility for Planning Fields | C40: Enhancement | D40: Supply Chain | E40: Tom Green | F40: ✅ COMPLETE | G40: 0.1 | H40: Highest | L40: Synnergie | N40: Audrey Debaere | Q40: S: < 80 Hours | R40: 80 | AC40: =IF(OR(ISNUMBER(SEARCH("POSTPONED",$F40)),ISNUMBER(SEARCH("NOT APPROVED",$F40))),2,IF(ISNUMBER(SEARCH("COMPLETE",$F40)),3,1)) -> 3
A41: ETE-32 | B41: Form: Cash App SQL Fix | C41: Enhancement | D41: Finance | E41: Tom Newell | F41: ✅ COMPLETE | G41: 1 | H41: High | L41: Synnergie | N41: Audrey Debaere | Q41: L: 160-320 Hours | R41: 320 | AC41: =IF(OR(ISNUMBER(SEARCH("POSTPONED",$F41)),ISNUMBER(SEARCH("NOT APPROVED",$F41))),2,IF(ISNUMBER(SEARCH("COMPLETE",$F41)),3,1)) -> 3
...

Sheet Project Timeline
A1: ETE IT PMO — Project Timeline (Gantt View)
A2: Auto-populated from Project Portfolio | Non-complete projects only | Red line = current week
G3: January 2026 | K3: February 2026 | O3: March 2026 | T3: April 2026 | X3: May 2026 | AB3: June 2026 | AG3: July 2026 | AK3: August 2026 | AP3: September 2026 | AT3: October 2026 | AX3: November 2026 | BC3: December 2026
A4: # | B4: Project ID | C4: Project Name | D4: Project Health | E4: Start | F4: End | G4: 46027 | H4: 46034 | I4: 46041 | J4: 46048 | K4: 46055 | L4: 46062 | M4: 46069 | N4: 46076 | O4: 46083 | P4: 46090 | Q4: 46097 | R4: 46104 | S4: 46111 | T4: 46118 | U4: 46125 | V4: 46132 | W4: 46139 | X4: 46146 | Y4: 46153 | Z4: 46160 | AA4: 46167 | AB4: 46174 | AC4: 46181 | AD4: 46188 | AE4: 46195 | AF4: 46202 | AG4: 46209 | AH4: 46216 | AI4: 46223 | AJ4: 46230 | AK4: 46237 | AL4: 46244 | AM4: 46251 | AN4: 46258 | AO4: 46265 | AP4: 46272 | AQ4: 46279 | AR4: 46286 | AS4: 46293 | AT4: 46300 | AU4: 46307 | AV4: 46314 | AW4: 46321 | AX4: 46328 | AY4: 46335 | AZ4: 46342 | BA4: 46349 | BB4: 46356 | BC4: 46363 | BD4: 46370 | BE4: 46377 | BF4: 46384
A5: 1 | B5: {=IFERROR(INDEX(_xlfn.SORTBY(_xlfn._xlws.FILTER('Project Portfolio'!A$4:A$43,('Project Portfolio'!F$4:F$43<>"✅ COMPLETE")*('Project Portfolio'!F$4:F$43<>"🚫 NOT APPROVED")*('Project Portfolio'!F$4:F$43<>"⏸️ POSTPONED")*('Project Portfolio'!A$4:A$43<>"")),_xlfn._xlws.FILTER(IF('Project Portfolio'!J$4:J$43=0,99999,'Project Portfolio'!J$4:J$43),('Project Portfolio'!F$4:F$43<>"✅ COMPLETE")*('Project Portfolio'!F$4:F$43<>"🚫 NOT APPROVED")*('Project Portfolio'!F$4:F$43<>"⏸️ POSTPONED")*('Project Portfolio'!A$4:A$43<>"")),1),ROW()-4),"")} -> ETE-19 | C5: {=IFERROR(INDEX(_xlfn.SORTBY(_xlfn._xlws.FILTER('Project Portfolio'!B$4:B$43,('Project Portfolio'!F$4:F$43<>"✅ COMPLETE")*('Project Portfolio'!F$4:F$43<>"🚫 NOT APPROVED")*('Project Portfolio'!F$4:F$43<>"⏸️ POSTPONED")*('Project Portfolio'!A$4:A$43<>"")),_xlfn._xlws.FILTER(IF('Project Portfolio'!J$4:J$43=0,99999,'Project Portfolio'!J$4:J$43),('Project Portfolio'!F$4:F$43<>"✅ COMPLETE")*('Project Portfolio'!F$4:F$43<>"🚫 NOT APPROVED")*('Project Portfolio'!F$4:F$43<>"⏸️ POSTPONED")*('Project Portfolio'!A$4:A$43<>"")),1),ROW()-4),"")} -> Changes to AR Aging Report | D5: {=IFERROR(INDEX(_xlfn.SORTBY(_xlfn._xlws.FILTER('Project Portfolio'!F$4:F$43,('Project Portfolio'!F$4:F$43<>"✅ COMPLETE")*('Project Portfolio'!F$4:F$43<>"🚫 NOT APPROVED")*('Project Portfolio'!F$4:F$43<>"⏸️ POSTPONED")*('Project Portfolio'!A$4:A$43<>"")),_xlfn._xlws.FILTER(IF('Project Portfolio'!J$4:J$43=0,99999,'Project Portfolio'!J$4:J$43),('Project Portfolio'!F$4:F$43<>"✅ COMPLETE")*('Project Portfolio'!F$4:F$43<>"🚫 NOT APPROVED")*('Project Portfolio'!F$4:F$43<>"⏸️ POSTPONED")*('Project Portfolio'!A$4:A$43<>"")),1),ROW()-4),"")} -> 🟢 ON TRACK | E5: {=IFERROR(IF(INDEX(_xlfn.SORTBY(_xlfn._xlws.FILTER('Project Portfolio'!I$4:I$43,('Project Portfolio'!F$4:F$43<>"✅ COMPLETE")*('Project Portfolio'!F$4:F$43<>"🚫 NOT APPROVED")*('Project Portfolio'!F$4:F$43<>"⏸️ POSTPONED")*('Project Portfolio'!A$4:A$43<>"")),_xlfn._xlws.FILTER(IF('Project Portfolio'!J$4:J$43=0,99999,'Project Portfolio'!J$4:J$43),('Project Portfolio'!F$4:F$43<>"✅ COMPLETE")*('Project Portfolio'!F$4:F$43<>"🚫 NOT APPROVED")*('Project Portfolio'!F$4:F$43<>"⏸️ POSTPONED")*('Project Portfolio'!A$4:A$43<>"")),1),ROW()-4)=0,"",INDEX(_xlfn.SORTBY(_xlfn._xlws.FILTER('Project Portfolio'!I$4:I$43,('Project Portfolio'!F$4:F$43<>"✅ COMPLETE")*('Project Portfolio'!F$4:F$43<>"🚫 NOT APPROVED")*('Project Portfolio'!F$4:F$43<>"⏸️ POSTPONED")*('Project Portfolio'!A$4:A$43<>"")),_xlfn._xlws.FILTER(IF('Project Portfolio'!J$4:J$43=0,99999,'Project Portfolio'!J$4:J$43),('Project Portfolio'!F$4:F$43<>"✅ COMPLETE")*('Project Portfolio'!F$4:F$43<>"🚫 NOT APPROVED")*('Project Portfolio'!F$4:F$43<>"⏸️ POSTPONED")*('Project Portfolio'!A$4:A$43<>"")),1),ROW()-4)),"")} -> 46076 | F5: {=IFERROR(IF(INDEX(_xlfn.SORTBY(_xlfn._xlws.FILTER('Project Portfolio'!J$4:J$43,('Project Portfolio'!F$4:F$43<>"✅ COMPLETE")*('Project Portfolio'!F$4:F$43<>"🚫 NOT APPROVED")*('Project Portfolio'!F$4:F$43<>"⏸️ POSTPONED")*('Project Portfolio'!A$4:A$43<>"")),_xlfn._xlws.FILTER(IF('Project Portfolio'!J$4:J$43=0,99999,'Project Portfolio'!J$4:J$43),('Project Portfolio'!F$4:F$43<>"✅ COMPLETE")*('Project Portfolio'!F$4:F$43<>"🚫 NOT APPROVED")*('Project Portfolio'!F$4:F$43<>"⏸️ POSTPONED")*('Project Portfolio'!A$4:A$43<>"")),1),ROW()-4)=0,"",INDEX(_xlfn.SORTBY(_xlfn._xlws.FILTER('Project Portfolio'!J$4:J$43,('Project Portfolio'!F$4:F$43<>"✅ COMPLETE")*('Project Portfolio'!F$4:F$43<>"🚫 NOT APPROVED")*('Project Portfolio'!F$4:F$43<>"⏸️ POSTPONED")*('Project Portfolio'!A$4:A$43<>"")),_xlfn._xlws.FILTER(IF('Project Portfolio'!J$4:J$43=0,99999,'Project Portfolio'!J$4:J$43),('Project Portfolio'!F$4:F$43<>"✅ COMPLETE")*('Project Portfolio'!F$4:F$43<>"🚫 NOT APPROVED")*('Project Portfolio'!F$4:F$43<>"⏸️ POSTPONED")*('Project Portfolio'!A$4:A$43<>"")),1),ROW()-4)),"")} -> 46129 | G5: =IF(AND($E5>0,$F5>0,G$4+6>=$E5,G$4<=$F5),1,"") | H5: =IF(AND($E5>0,$F5>0,H$4+6>=$E5,H$4<=$F5),1,"") | I5: =IF(AND($E5>0,$F5>0,I$4+6>=$E5,I$4<=$F5),1,"") | J5: =IF(AND($E5>0,$F5>0,J$4+6>=$E5,J$4<=$F5),1,"") | K5: =IF(AND($E5>0,$F5>0,K$4+6>=$E5,K$4<=$F5),1,"") | L5: =IF(AND($E5>0,$F5>0,L$4+6>=$E5,L$4<=$F5),1,"") | M5: =IF(AND($E5>0,$F5>0,M$4+6>=$E5,M$4<=$F5),1,"") | N5: =IF(AND($E5>0,$F5>0,N$4+6>=$E5,N$4<=$F5),1,"") -> 1 | ... BF5: =IF(AND($E5>0,$F5>0,BF$4+6>=$E5,BF$4<=$F5),1,"")
A6: 2 | B6: {=IFERROR(INDEX(_xlfn.SORTBY(_xlfn._xlws.FILTER('Project Portfolio'!A$4:A$43,('Project Portfolio'!F$4:F$43<>"✅ COMPLETE")*('Project Portfolio'!F$4:F$43<>"🚫 NOT APPROVED")*('Project Portfolio'!F$4:F$43<>"⏸️ POSTPONED")*('Project Portfolio'!A$4:A$43<>"")),_xlfn._xlws.FILTER(IF('Project Portfolio'!J$4:J$43=0,99999,'Project Portfolio'!J$4:J$43),('Project Portfolio'!F$4:F$43<>"✅ COMPLETE")*('Project Portfolio'!F$4:F$43<>"🚫 NOT APPROVED")*('Project Portfolio'!F$4:F$43<>"⏸️ POSTPONED")*('Project Portfolio'!A$4:A$43<>"")),1),ROW()-4),"")} -> ETE-68 | C6: {=IFERROR(INDEX(_xlfn.SORTBY(_xlfn._xlws.FILTER('Project Portfolio'!B$4:B$43,('Project Portfolio'!F$4:F$43<>"✅ COMPLETE")*('Project Portfolio'!F$4:F$43<>"🚫 NOT APPROVED")*('Project Portfolio'!F$4:F$43<>"⏸️ POSTPONED")*('Project Portfolio'!A$4:A$43<>"")),_xlfn._xlws.FILTER(IF('Project Portfolio'!J$4:J$43=0,99999,'Project Portfolio'!J$4:J$43),('Project Portfolio'!F$4:F$43<>"✅ COMPLETE")*('Project Portfolio'!F$4:F$43<>"🚫 NOT APPROVED")*('Project Portfolio'!F$4:F$43<>"⏸️ POSTPONED")*('Project Portfolio'!A$4:A$43<>"")),1),ROW()-4),"")} -> Catalog API Rust2Python | D6: {=IFERROR(INDEX(_xlfn.SORTBY(_xlfn._xlws.FILTER('Project Portfolio'!F$4:F$43,('Project Portfolio'!F$4:F$43<>"✅ COMPLETE")*('Project Portfolio'!F$4:F$43<>"🚫 NOT APPROVED")*('Project Portfolio'!F$4:F$43<>"⏸️ POSTPONED")*('Project Portfolio'!A$4:A$43<>"")),_xlfn._xlws.FILTER(IF('Project Portfolio'!J$4:J$43=0,99999,'Project Portfolio'!J$4:J$43),('Project Portfolio'!F$4:F$43<>"✅ COMPLETE")*('Project Portfolio'!F$4:F$43<>"🚫 NOT APPROVED")*('Project Portfolio'!F$4:F$43<>"⏸️ POSTPONED")*('Project Portfolio'!A$4:A$43<>"")),1),ROW()-4),"")} -> 🟢 ON TRACK | E6: {=IFERROR(IF(INDEX(_xlfn.SORTBY(_xlfn._xlws.FILTER('Project Portfolio'!I$4:I$43,('Project Portfolio'!F$4:F$43<>"✅ COMPLETE")*('Project Portfolio'!F$4:F$43<>"🚫 NOT APPROVED")*('Project Portfolio'!F$4:F$43<>"⏸️ POSTPONED")*('Project Portfolio'!A$4:A$43<>"")),_xlfn._xlws.FILTER(IF('Project Portfolio'!J$4:J$43=0,99999,'Project Portfolio'!J$4:J$43),('Project Portfolio'!F$4:F$43<>"✅ COMPLETE")*('Project Portfolio'!F$4:F$43<>"🚫 NOT APPROVED")*('Project Portfolio'!F$4:F$43<>"⏸️ POSTPONED")*('Project Portfolio'!A$4:A$43<>"")),1),ROW()-4)=0,"",INDEX(_xlfn.SORTBY(_xlfn._xlws.FILTER('Project Portfolio'!I$4:I$43,('Project Portfolio'!F$4:F$43<>"✅ COMPLETE")*('Project Portfolio'!F$4:F$43<>"🚫 NOT APPROVED")*('Project Portfolio'!F$4:F$43<>"⏸️ POSTPONED")*('Project Portfolio'!A$4:A$43<>"")),_xlfn._xlws.FILTER(IF('Project Portfolio'!J$4:J$43=0,99999,'Project Portfolio'!J$4:J$43),('Project Portfolio'!F$4:F$43<>"✅ COMPLETE")*('Project Portfolio'!F$4:F$43<>"🚫 NOT APPROVED")*('Project Portfolio'!F$4:F$43<>"⏸️ POSTPONED")*('Project Portfolio'!A$4:A$43<>"")),1),ROW()-4)),"")} -> 45978 | F6: {=IFERROR(IF(INDEX(_xlfn.SORTBY(_xlfn._xlws.FILTER('Project Portfolio'!J$4:J$43,('Project Portfolio'!F$4:F$43<>"✅ COMPLETE")*('Project Portfolio'!F$4:F$43<>"🚫 NOT APPROVED")*('Project Portfolio'!F$4:F$43<>"⏸️ POSTPONED")*('Project Portfolio'!A$4:A$43<>"")),_xlfn._xlws.FILTER(IF('Project Portfolio'!J$4:J$43=0,99999,'Project Portfolio'!J$4:J$43),('Project Portfolio'!F$4:F$43<>"✅ COMPLETE")*('Project Portfolio'!F$4:F$43<>"🚫 NOT APPROVED")*('Project Portfolio'!F$4:F$43<>"⏸️ POSTPONED")*('Project Portfolio'!A$4:A$43<>"")),1),ROW()-4)=0,"",INDEX(_xlfn.SORTBY(_xlfn._xlws.FILTER('Project Portfolio'!J$4:J$43,('Project Portfolio'!F$4:F$43<>"✅ COMPLETE")*('Project Portfolio'!F$4:F$43<>"🚫 NOT APPROVED")*('Project Portfolio'!F$4:F$43<>"⏸️ POSTPONED")*('Project Portfolio'!A$4:A$43<>"")),_xlfn._xlws.FILTER(IF('Project Portfolio'!J$4:J$43=0,99999,'Project Portfolio'!J$4:J$43),('Project Portfolio'!F$4:F$43<>"✅ COMPLETE")*('Project Portfolio'!F$4:F$43<>"🚫 NOT APPROVED")*('Project Portfolio'!F$4:F$43<>"⏸️ POSTPONED")*('Project Portfolio'!A$4:A$43<>"")),1),ROW()-4)),"")} -> 46136 | G6: =IF(AND($E6>0,$F6>0,G$4+6>=$E6,G$4<=$F6),1,"") -> 1 | H6: =IF(AND($E6>0,$F6>0,H$4+6>=$E6,H$4<=$F6),1,"") -> 1 | I6: =IF(AND($E6>0,$F6>0,I$4+6>=$E6,I$4<=$F6),1,"") -> 1 | J6: =IF(AND($E6>0,$F6>0,J$4+6>=$E6,J$4<=$F6),1,"") -> 1 | K6: =IF(AND($E6>0,$F6>0,K$4+6>=$E6,K$4<=$F6),1,"") -> 1 | L6: =IF(AND($E6>0,$F6>0,L$4+6>=$E6,L$4<=$F6),1,"") -> 1 | M6: =IF(AND($E6>0,$F6>0,M$4+6>=$E6,M$4<=$F6),1,"") -> 1 | N6: =IF(AND($E6>0,$F6>0,N$4+6>=$E6,N$4<=$F6),1,"") -> 1 | ... BF6: =IF(AND($E6>0,$F6>0,BF$4+6>=$E6,BF$4<=$F6),1,"")
A7: 3 | B7: {=IFERROR(INDEX(_xlfn.SORTBY(_xlfn._xlws.FILTER('Project Portfolio'!A$4:A$43,('Project Portfolio'!F$4:F$43<>"✅ COMPLETE")*('Project Portfolio'!F$4:F$43<>"🚫 NOT APPROVED")*('Project Portfolio'!F$4:F$43<>"⏸️ POSTPONED")*('Project Portfolio'!A$4:A$43<>"")),_xlfn._xlws.FILTER(IF('Project Portfolio'!J$4:J$43=0,99999,'Project Portfolio'!J$4:J$43),('Project Portfolio'!F$4:F$43<>"✅ COMPLETE")*('Project Portfolio'!F$4:F$43<>"🚫 NOT APPROVED")*('Project Portfolio'!F$4:F$43<>"⏸️ POSTPONED")*('Project Portfolio'!A$4:A$43<>"")),1),ROW()-4),"")} -> ETE-83 | C7: {=IFERROR(INDEX(_xlfn.SORTBY(_xlfn._xlws.FILTER('Project Portfolio'!B$4:B$43,('Project Portfolio'!F$4:F$43<>"✅ COMPLETE")*('Project Portfolio'!F$4:F$43<>"🚫 NOT APPROVED")*('Project Portfolio'!F$4:F$43<>"⏸️ POSTPONED")*('Project Portfolio'!A$4:A$43<>"")),_xlfn._xlws.FILTER(IF('Project Portfolio'!J$4:J$43=0,99999,'Project Portfolio'!J$4:J$43),('Project Portfolio'!F$4:F$43<>"✅ COMPLETE")*('Project Portfolio'!F$4:F$43<>"🚫 NOT APPROVED")*('Project Portfolio'!F$4:F$43<>"⏸️ POSTPONED")*('Project Portfolio'!A$4:A$43<>"")),1),ROW()-4),"")} -> Customer Master Data Cleanup | D7: {=IFERROR(INDEX(_xlfn.SORTBY(_xlfn._xlws.FILTER('Project Portfolio'!F$4:F$43,('Project Portfolio'!F$4:F$43<>"✅ COMPLETE")*('Project Portfolio'!F$4:F$43<>"🚫 NOT APPROVED")*('Project Portfolio'!F$4:F$43<>"⏸️ POSTPONED")*('Project Portfolio'!A$4:A$43<>"")),_xlfn._xlws.FILTER(IF('Project Portfolio'!J$4:J$43=0,99999,'Project Portfolio'!J$4:J$43),('Project Portfolio'!F$4:F$43<>"✅ COMPLETE")*('Project Portfolio'!F$4:F$43<>"🚫 NOT APPROVED")*('Project Portfolio'!F$4:F$43<>"⏸️ POSTPONED")*('Project Portfolio'!A$4:A$43<>"")),1),ROW()-4),"")} -> 📋 NEEDS TECHNICAL SPEC | E7: {=IFERROR(IF(INDEX(_xlfn.SORTBY(_xlfn._xlws.FILTER('Project Portfolio'!I$4:I$43,('Project Portfolio'!F$4:F$43<>"✅ COMPLETE")*('Project Portfolio'!F$4:F$43<>"🚫 NOT APPROVED")*('Project Portfolio'!F$4:F$43<>"⏸️ POSTPONED")*('Project Portfolio'!A$4:A$43<>"")),_xlfn._xlws.FILTER(IF('Project Portfolio'!J$4:J$43=0,99999,'Project Portfolio'!J$4:J$43),('Project Portfolio'!F$4:F$43<>"✅ COMPLETE")*('Project Portfolio'!F$4:F$43<>"🚫 NOT APPROVED")*('Project Portfolio'!F$4:F$43<>"⏸️ POSTPONED")*('Project Portfolio'!A$4:A$43<>"")),1),ROW()-4)=0,"",INDEX(_xlfn.SORTBY(_xlfn._xlws.FILTER('Project Portfolio'!I$4:I$43,('Project Portfolio'!F$4:F$43<>"✅ COMPLETE")*('Project Portfolio'!F$4:F$43<>"🚫 NOT APPROVED")*('Project Portfolio'!F$4:F$43<>"⏸️ POSTPONED")*('Project Portfolio'!A$4:A$43<>"")),_xlfn._xlws.FILTER(IF('Project Portfolio'!J$4:J$43=0,99999,'Project Portfolio'!J$4:J$43),('Project Portfolio'!F$4:F$43<>"✅ COMPLETE")*('Project Portfolio'!F$4:F$43<>"🚫 NOT APPROVED")*('Project Portfolio'!F$4:F$43<>"⏸️ POSTPONED")*('Project Portfolio'!A$4:A$43<>"")),1),ROW()-4)),"")} -> 45944 | F7: {=IFERROR(IF(INDEX(_xlfn.SORTBY(_xlfn._xlws.FILTER('Project Portfolio'!J$4:J$43,('Project Portfolio'!F$4:F$43<>"✅ COMPLETE")*('Project Portfolio'!F$4:F$43<>"🚫 NOT APPROVED")*('Project Portfolio'!F$4:F$43<>"⏸️ POSTPONED")*('Project Portfolio'!A$4:A$43<>"")),_xlfn._xlws.FILTER(IF('Project Portfolio'!J$4:J$43=0,99999,'Project Portfolio'!J$4:J$43),('Project Portfolio'!F$4:F$43<>"✅ COMPLETE")*('Project Portfolio'!F$4:F$43<>"🚫 NOT APPROVED")*('Project Portfolio'!F$4:F$43<>"⏸️ POSTPONED")*('Project Portfolio'!A$4:A$43<>"")),1),ROW()-4)=0,"",INDEX(_xlfn.SORTBY(_xlfn._xlws.FILTER('Project Portfolio'!J$4:J$43,('Project Portfolio'!F$4:F$43<>"✅ COMPLETE")*('Project Portfolio'!F$4:F$43<>"🚫 NOT APPROVED")*('Project Portfolio'!F$4:F$43<>"⏸️ POSTPONED")*('Project Portfolio'!A$4:A$43<>"")),_xlfn._xlws.FILTER(IF('Project Portfolio'!J$4:J$43=0,99999,'Project Portfolio'!J$4:J$43),('Project Portfolio'!F$4:F$43<>"✅ COMPLETE")*('Project Portfolio'!F$4:F$43<>"🚫 NOT APPROVED")*('Project Portfolio'!F$4:F$43<>"⏸️ POSTPONED")*('Project Portfolio'!A$4:A$43<>"")),1),ROW()-4)),"")} -> 46174 | G7: =IF(AND($E7>0,$F7>0,G$4+6>=$E7,G$4<=$F7),1,"") -> 1 | H7: =IF(AND($E7>0,$F7>0,H$4+6>=$E7,H$4<=$F7),1,"") -> 1 | I7: =IF(AND($E7>0,$F7>0,I$4+6>=$E7,I$4<=$F7),1,"") -> 1 | J7: =IF(AND($E7>0,$F7>0,J$4+6>=$E7,J$4<=$F7),1,"") -> 1 | K7: =IF(AND($E7>0,$F7>0,K$4+6>=$E7,K$4<=$F7),1,"") -> 1 | L7: =IF(AND($E7>0,$F7>0,L$4+6>=$E7,L$4<=$F7),1,"") -> 1 | M7: =IF(AND($E7>0,$F7>0,M$4+6>=$E7,M$4<=$F7),1,"") -> 1 | N7: =IF(AND($E7>0,$F7>0,N$4+6>=$E7,N$4<=$F7),1,"") -> 1 | ... BF7: =IF(AND($E7>0,$F7>0,BF$4+6>=$E7,BF$4<=$F7),1,"")
A8: 4 | B8: {=IFERROR(INDEX(_xlfn.SORTBY(_xlfn._xlws.FILTER('Project Portfolio'!A$4:A$43,('Project Portfolio'!F$4:F$43<>"✅ COMPLETE")*('Project Portfolio'!F$4:F$43<>"🚫 NOT APPROVED")*('Project Portfolio'!F$4:F$43<>"⏸️ POSTPONED")*('Project Portfolio'!A$4:A$43<>"")),_xlfn._xlws.FILTER(IF('Project Portfolio'!J$4:J$43=0,99999,'Project Portfolio'!J$4:J$43),('Project Portfolio'!F$4:F$43<>"✅ COMPLETE")*('Project Portfolio'!F$4:F$43<>"🚫 NOT APPROVED")*('Project Portfolio'!F$4:F$43<>"⏸️ POSTPONED")*('Project Portfolio'!A$4:A$43<>"")),1),ROW()-4),"")} -> ETE-48 | C8: {=IFERROR(INDEX(_xlfn.SORTBY(_xlfn._xlws.FILTER('Project Portfolio'!B$4:B$43,('Project Portfolio'!F$4:F$43<>"✅ COMPLETE")*('Project Portfolio'!F$4:F$43<>"🚫 NOT APPROVED")*('Project Portfolio'!F$4:F$43<>"⏸️ POSTPONED")*('Project Portfolio'!A$4:A$43<>"")),_xlfn._xlws.FILTER(IF('Project Portfolio'!J$4:J$43=0,99999,'Project Portfolio'!J$4:J$43),('Project Portfolio'!F$4:F$43<>"✅ COMPLETE")*('Project Portfolio'!F$4:F$43<>"🚫 NOT APPROVED")*('Project Portfolio'!F$4:F$43<>"⏸️ POSTPONED")*('Project Portfolio'!A$4:A$43<>"")),1),ROW()-4),"")} -> System Connection Syteline-VKS | D8: {=IFERROR(INDEX(_xlfn.SORTBY(_xlfn._xlws.FILTER('Project Portfolio'!F$4:F$43,('Project Portfolio'!F$4:F$43<>"✅ COMPLETE")*('Project Portfolio'!F$4:F$43<>"🚫 NOT APPROVED")*('Project Portfolio'!F$4:F$43<>"⏸️ POSTPONED")*('Project Portfolio'!A$4:A$43<>"")),_xlfn._xlws.FILTER(IF('Project Portfolio'!J$4:J$43=0,99999,'Project Portfolio'!J$4:J$43),('Project Portfolio'!F$4:F$43<>"✅ COMPLETE")*('Project Portfolio'!F$4:F$43<>"🚫 NOT APPROVED")*('Project Portfolio'!F$4:F$43<>"⏸️ POSTPONED")*('Project Portfolio'!A$4:A$43<>"")),1),ROW()-4),"")} -> 🟢 ON TRACK | E8: {=IFERROR(IF(INDEX(_xlfn.SORTBY(_xlfn._xlws.FILTER('Project Portfolio'!I$4:I$43,('Project Portfolio'!F$4:F$43<>"✅ COMPLETE")*('Project Portfolio'!F$4:F$43<>"🚫 NOT APPROVED")*('Project Portfolio'!F$4:F$43<>"⏸️ POSTPONED")*('Project Portfolio'!A$4:A$43<>"")),_xlfn._xlws.FILTER(IF('Project Portfolio'!J$4:J$43=0,99999,'Project Portfolio'!J$4:J$43),('Project Portfolio'!F$4:F$43<>"✅ COMPLETE")*('Project Portfolio'!F$4:F$43<>"🚫 NOT APPROVED")*('Project Portfolio'!F$4:F$43<>"⏸️ POSTPONED")*('Project Portfolio'!A$4:A$43<>"")),1),ROW()-4)=0,"",INDEX(_xlfn.SORTBY(_xlfn._xlws.FILTER('Project Portfolio'!I$4:I$43,('Project Portfolio'!F$4:F$43<>"✅ COMPLETE")*('Project Portfolio'!F$4:F$43<>"🚫 NOT APPROVED")*('Project Portfolio'!F$4:F$43<>"⏸️ POSTPONED")*('Project Portfolio'!A$4:A$43<>"")),_xlfn._xlws.FILTER(IF('Project Portfolio'!J$4:J$43=0,99999,'Project Portfolio'!J$4:J$43),('Project Portfolio'!F$4:F$43<>"✅ COMPLETE")*('Project Portfolio'!F$4:F$43<>"🚫 NOT APPROVED")*('Project Portfolio'!F$4:F$43<>"⏸️ POSTPONED")*('Project Portfolio'!A$4:A$43<>"")),1),ROW()-4)),"")} -> 46068 | F8: {=IFERROR(IF(INDEX(_xlfn.SORTBY(_xlfn._xlws.FILTER('Project Portfolio'!J$4:J$43,('Project Portfolio'!F$4:F$43<>"✅ COMPLETE")*('Project Portfolio'!F$4:F$43<>"🚫 NOT APPROVED")*('Project Portfolio'!F$4:F$43<>"⏸️ POSTPONED")*('Project Portfolio'!A$4:A$43<>"")),_xlfn._xlws.FILTER(IF('Project Portfolio'!J$4:J$43=0,99999,'Project Portfolio'!J$4:J$43),('Project Portfolio'!F$4:F$43<>"✅ COMPLETE")*('Project Portfolio'!F$4:F$43<>"🚫 NOT APPROVED")*('Project Portfolio'!F$4:F$43<>"⏸️ POSTPONED")*('Project Portfolio'!A$4:A$43<>"")),1),ROW()-4)=0,"",INDEX(_xlfn.SORTBY(_xlfn._xlws.FILTER('Project Portfolio'!J$4:J$43,('Project Portfolio'!F$4:F$43<>"✅ COMPLETE")*('Project Portfolio'!F$4:F$43<>"🚫 NOT APPROVED")*('Project Portfolio'!F$4:F$43<>"⏸️ POSTPONED")*('Project Portfolio'!A$4:A$43<>"")),_xlfn._xlws.FILTER(IF('Project Portfolio'!J$4:J$43=0,99999,'Project Portfolio'!J$4:J$43),('Project Portfolio'!F$4:F$43<>"✅ COMPLETE")*('Project Portfolio'!F$4:F$43<>"🚫 NOT APPROVED")*('Project Portfolio'!F$4:F$43<>"⏸️ POSTPONED")*('Project Portfolio'!A$4:A$43<>"")),1),ROW()-4)),"")} -> 46203 | G8: =IF(AND($E8>0,$F8>0,G$4+6>=$E8,G$4<=$F8),1,"") | H8: =IF(AND($E8>0,$F8>0,H$4+6>=$E8,H$4<=$F8),1,"") | I8: =IF(AND($E8>0,$F8>0,I$4+6>=$E8,I$4<=$F8),1,"") | J8: =IF(AND($E8>0,$F8>0,J$4+6>=$E8,J$4<=$F8),1,"") | K8: =IF(AND($E8>0,$F8>0,K$4+6>=$E8,K$4<=$F8),1,"") | L8: =IF(AND($E8>0,$F8>0,L$4+6>=$E8,L$4<=$F8),1,"") -> 1 | M8: =IF(AND($E8>0,$F8>0,M$4+6>=$E8,M$4<=$F8),1,"") -> 1 | N8: =IF(AND($E8>0,$F8>0,N$4+6>=$E8,N$4<=$F8),1,"") -> 1 | ... BF8: =IF(AND($E8>0,$F8>0,BF$4+6>=$E8,BF$4<=$F8),1,"")
A9: 5 | B9: {=IFERROR(INDEX(_xlfn.SORTBY(_xlfn._xlws.FILTER('Project Portfolio'!A$4:A$43,('Project Portfolio'!F$4:F$43<>"✅ COMPLETE")*('Project Portfolio'!F$4:F$43<>"🚫 NOT APPROVED")*('Project Portfolio'!F$4:F$43<>"⏸️ POSTPONED")*('Project Portfolio'!A$4:A$43<>"")),_xlfn._xlws.FILTER(IF('Project Portfolio'!J$4:J$43=0,99999,'Project Portfolio'!J$4:J$43),('Project Portfolio'!F$4:F$43<>"✅ COMPLETE")*('Project Portfolio'!F$4:F$43<>"🚫 NOT APPROVED")*('Project Portfolio'!F$4:F$43<>"⏸️ POSTPONED")*('Project Portfolio'!A$4:A$43<>"")),1),ROW()-4),"")} -> ETE-43 | C9: {=IFERROR(INDEX(_xlfn.SORTBY(_xlfn._xlws.FILTER('Project Portfolio'!B$4:B$43,('Project Portfolio'!F$4:F$43<>"✅ COMPLETE")*('Project Portfolio'!F$4:F$43<>"🚫 NOT APPROVED")*('Project Portfolio'!F$4:F$43<>"⏸️ POSTPONED")*('Project Portfolio'!A$4:A$43<>"")),_xlfn._xlws.FILTER(IF('Project Portfolio'!J$4:J$43=0,99999,'Project Portfolio'!J$4:J$43),('Project Portfolio'!F$4:F$43<>"✅ COMPLETE")*('Project Portfolio'!F$4:F$43<>"🚫 NOT APPROVED")*('Project Portfolio'!F$4:F$43<>"⏸️ POSTPONED")*('Project Portfolio'!A$4:A$43<>"")),1),ROW()-4),"")} -> Data Security - Microsoft Purview | D9: {=IFERROR(INDEX(_xlfn.SORTBY(_xlfn._xlws.FILTER('Project Portfolio'!F$4:F$43,('Project Portfolio'!F$4:F$43<>"✅ COMPLETE")*('Project Portfolio'!F$4:F$43<>"🚫 NOT APPROVED")*('Project Portfolio'!F$4:F$43<>"⏸️ POSTPONED")*('Project Portfolio'!A$4:A$43<>"")),_xlfn._xlws.FILTER(IF('Project Portfolio'!J$4:J$43=0,99999,'Project Portfolio'!J$4:J$43),('Project Portfolio'!F$4:F$43<>"✅ COMPLETE")*('Project Portfolio'!F$4:F$43<>"🚫 NOT APPROVED")*('Project Portfolio'!F$4:F$43<>"⏸️ POSTPONED")*('Project Portfolio'!A$4:A$43<>"")),1),ROW()-4),"")} -> 🟢 ON TRACK | E9: {=IFERROR(IF(INDEX(_xlfn.SORTBY(_xlfn._xlws.FILTER('Project Portfolio'!I$4:I$43,('Project Portfolio'!F$4:F$43<>"✅ COMPLETE")*('Project Portfolio'!F$4:F$43<>"🚫 NOT APPROVED")*('Project Portfolio'!F$4:F$43<>"⏸️ POSTPONED")*('Project Portfolio'!A$4:A$43<>"")),_xlfn._xlws.FILTER(IF('Project Portfolio'!J$4:J$43=0,99999,'Project Portfolio'!J$4:J$43),('Project Portfolio'!F$4:F$43<>"✅ COMPLETE")*('Project Portfolio'!F$4:F$43<>"🚫 NOT APPROVED")*('Project Portfolio'!F$4:F$43<>"⏸️ POSTPONED")*('Project Portfolio'!A$4:A$43<>"")),1),ROW()-4)=0,"",INDEX(_xlfn.SORTBY(_xlfn._xlws.FILTER('Project Portfolio'!I$4:I$43,('Project Portfolio'!F$4:F$43<>"✅ COMPLETE")*('Project Portfolio'!F$4:F$43<>"🚫 NOT APPROVED")*('Project Portfolio'!F$4:F$43<>"⏸️ POSTPONED")*('Project Portfolio'!A$4:A$43<>"")),_xlfn._xlws.FILTER(IF('Project Portfolio'!J$4:J$43=0,99999,'Project Portfolio'!J$4:J$43),('Project Portfolio'!F$4:F$43<>"✅ COMPLETE")*('Project Portfolio'!F$4:F$43<>"🚫 NOT APPROVED")*('Project Portfolio'!F$4:F$43<>"⏸️ POSTPONED")*('Project Portfolio'!A$4:A$43<>"")),1),ROW()-4)),"")} -> 46055 | F9: {=IFERROR(IF(INDEX(_xlfn.SORTBY(_xlfn._xlws.FILTER('Project Portfolio'!J$4:J$43,('Project Portfolio'!F$4:F$43<>"✅ COMPLETE")*('Project Portfolio'!F$4:F$43<>"🚫 NOT APPROVED")*('Project Portfolio'!F$4:F$43<>"⏸️ POSTPONED")*('Project Portfolio'!A$4:A$43<>"")),_xlfn._xlws.FILTER(IF('Project Portfolio'!J$4:J$43=0,99999,'Project Portfolio'!J$4:J$43),('Project Portfolio'!F$4:F$43<>"✅ COMPLETE")*('Project Portfolio'!F$4:F$43<>"🚫 NOT APPROVED")*('Project Portfolio'!F$4:F$43<>"⏸️ POSTPONED")*('Project Portfolio'!A$4:A$43<>"")),1),ROW()-4)=0,"",INDEX(_xlfn.SORTBY(_xlfn._xlws.FILTER('Project Portfolio'!J$4:J$43,('Project Portfolio'!F$4:F$43<>"✅ COMPLETE")*('Project Portfolio'!F$4:F$43<>"🚫 NOT APPROVED")*('Project Portfolio'!F$4:F$43<>"⏸️ POSTPONED")*('Project Portfolio'!A$4:A$43<>"")),_xlfn._xlws.FILTER(IF('Project Portfolio'!J$4:J$43=0,99999,'Project Portfolio'!J$4:J$43),('Project Portfolio'!F$4:F$43<>"✅ COMPLETE")*('Project Portfolio'!F$4:F$43<>"🚫 NOT APPROVED")*('Project Portfolio'!F$4:F$43<>"⏸️ POSTPONED")*('Project Portfolio'!A$4:A$43<>"")),1),ROW()-4)),"")} -> 46203 | G9: =IF(AND($E9>0,$F9>0,G$4+6>=$E9,G$4<=$F9),1,"") | H9: =IF(AND($E9>0,$F9>0,H$4+6>=$E9,H$4<=$F9),1,"") | I9: =IF(AND($E9>0,$F9>0,I$4+6>=$E9,I$4<=$F9),1,"") | J9: =IF(AND($E9>0,$F9>0,J$4+6>=$E9,J$4<=$F9),1,"") | K9: =IF(AND($E9>0,$F9>0,K$4+6>=$E9,K$4<=$F9),1,"") -> 1 | L9: =IF(AND($E9>0,$F9>0,L$4+6>=$E9,L$4<=$F9),1,"") -> 1 | M9: =IF(AND($E9>0,$F9>0,M$4+6>=$E9,M$4<=$F9),1,"") -> 1 | N9: =IF(AND($E9>0,$F9>0,N$4+6>=$E9,N$4<=$F9),1,"") -> 1 | ... BF9: =IF(AND($E9>0,$F9>0,BF$4+6>=$E9,BF$4<=$F9),1,"")
A10: 6 | B10: {=IFERROR(INDEX(_xlfn.SORTBY(_xlfn._xlws.FILTER('Project Portfolio'!A$4:A$43,('Project Portfolio'!F$4:F$43<>"✅ COMPLETE")*('Project Portfolio'!F$4:F$43<>"🚫 NOT APPROVED")*('Project Portfolio'!F$4:F$43<>"⏸️ POSTPONED")*('Project Portfolio'!A$4:A$43<>"")),_xlfn._xlws.FILTER(IF('Project Portfolio'!J$4:J$43=0,99999,'Project Portfolio'!J$4:J$43),('Project Portfolio'!F$4:F$43<>"✅ COMPLETE")*('Project Portfolio'!F$4:F$43<>"🚫 NOT APPROVED")*('Project Portfolio'!F$4:F$43<>"⏸️ POSTPONED")*('Project Portfolio'!A$4:A$43<>"")),1),ROW()-4),"")} -> ETE-49 | C10: {=IFERROR(INDEX(_xlfn.SORTBY(_xlfn._xlws.FILTER('Project Portfolio'!B$4:B$43,('Project Portfolio'!F$4:F$43<>"✅ COMPLETE")*('Project Portfolio'!F$4:F$43<>"🚫 NOT APPROVED")*('Project Portfolio'!F$4:F$43<>"⏸️ POSTPONED")*('Project Portfolio'!A$4:A$43<>"")),_xlfn._xlws.FILTER(IF('Project Portfolio'!J$4:J$43=0,99999,'Project Portfolio'!J$4:J$43),('Project Portfolio'!F$4:F$43<>"✅ COMPLETE")*('Project Portfolio'!F$4:F$43<>"🚫 NOT APPROVED")*('Project Portfolio'!F$4:F$43<>"⏸️ POSTPONED")*('Project Portfolio'!A$4:A$43<>"")),1),ROW()-4),"")} -> Marketing: STE Rewards Tier | D10: {=IFERROR(INDEX(_xlfn.SORTBY(_xlfn._xlws.FILTER('Project Portfolio'!F$4:F$43,('Project Portfolio'!F$4:F$43<>"✅ COMPLETE")*('Project Portfolio'!F$4:F$43<>"🚫 NOT APPROVED")*('Project Portfolio'!F$4:F$43<>"⏸️ POSTPONED")*('Project Portfolio'!A$4:A$43<>"")),_xlfn._xlws.FILTER(IF('Project Portfolio'!J$4:J$43=0,99999,'Project Portfolio'!J$4:J$43),('Project Portfolio'!F$4:F$43<>"✅ COMPLETE")*('Project Portfolio'!F$4:F$43<>"🚫 NOT APPROVED")*('Project Portfolio'!F$4:F$43<>"⏸️ POSTPONED")*('Project Portfolio'!A$4:A$43<>"")),1),ROW()-4),"")} -> 📋 NEEDS TECHNICAL SPEC | E10: {=IFERROR(IF(INDEX(_xlfn.SORTBY(_xlfn._xlws.FILTER('Project Portfolio'!I$4:I$43,('Project Portfolio'!F$4:F$43<>"✅ COMPLETE")*('Project Portfolio'!F$4:F$43<>"🚫 NOT APPROVED")*('Project Portfolio'!F$4:F$43<>"⏸️ POSTPONED")*('Project Portfolio'!A$4:A$43<>"")),_xlfn._xlws.FILTER(IF('Project Portfolio'!J$4:J$43=0,99999,'Project Portfolio'!J$4:J$43),('Project Portfolio'!F$4:F$43<>"✅ COMPLETE")*('Project Portfolio'!F$4:F$43<>"🚫 NOT APPROVED")*('Project Portfolio'!F$4:F$43<>"⏸️ POSTPONED")*('Project Portfolio'!A$4:A$43<>"")),1),ROW()-4)=0,"",INDEX(_xlfn.SORTBY(_xlfn._xlws.FILTER('Project Portfolio'!I$4:I$43,('Project Portfolio'!F$4:F$43<>"✅ COMPLETE")*('Project Portfolio'!F$4:F$43<>"🚫 NOT APPROVED")*('Project Portfolio'!F$4:F$43<>"⏸️ POSTPONED")*('Project Portfolio'!A$4:A$43<>"")),_xlfn._xlws.FILTER(IF('Project Portfolio'!J$4:J$43=0,99999,'Project Portfolio'!J$4:J$43),('Project Portfolio'!F$4:F$43<>"✅ COMPLETE")*('Project Portfolio'!F$4:F$43<>"🚫 NOT APPROVED")*('Project Portfolio'!F$4:F$43<>"⏸️ POSTPONED")*('Project Portfolio'!A$4:A$43<>"")),1),ROW()-4)),"")} | F10: {=IFERROR(IF(INDEX(_xlfn.SORTBY(_xlfn._xlws.FILTER('Project Portfolio'!J$4:J$43,('Project Portfolio'!F$4:F$43<>"✅ COMPLETE")*('Project Portfolio'!F$4:F$43<>"🚫 NOT APPROVED")*('Project Portfolio'!F$4:F$43<>"⏸️ POSTPONED")*('Project Portfolio'!A$4:A$43<>"")),_xlfn._xlws.FILTER(IF('Project Portfolio'!J$4:J$43=0,99999,'Project Portfolio'!J$4:J$43),('Project Portfolio'!F$4:F$43<>"✅ COMPLETE")*('Project Portfolio'!F$4:F$43<>"🚫 NOT APPROVED")*('Project Portfolio'!F$4:F$43<>"⏸️ POSTPONED")*('Project Portfolio'!A$4:A$43<>"")),1),ROW()-4)=0,"",INDEX(_xlfn.SORTBY(_xlfn._xlws.FILTER('Project Portfolio'!J$4:J$43,('Project Portfolio'!F$4:F$43<>"✅ COMPLETE")*('Project Portfolio'!F$4:F$43<>"🚫 NOT APPROVED")*('Project Portfolio'!F$4:F$43<>"⏸️ POSTPONED")*('Project Portfolio'!A$4:A$43<>"")),_xlfn._xlws.FILTER(IF('Project Portfolio'!J$4:J$43=0,99999,'Project Portfolio'!J$4:J$43),('Project Portfolio'!F$4:F$43<>"✅ COMPLETE")*('Project Portfolio'!F$4:F$43<>"🚫 NOT APPROVED")*('Project Portfolio'!F$4:F$43<>"⏸️ POSTPONED")*('Project Portfolio'!A$4:A$43<>"")),1),ROW()-4)),"")} | G10: =IF(AND($E10>0,$F10>0,G$4+6>=$E10,G$4<=$F10),1,"") | H10: =IF(AND($E10>0,$F10>0,H$4+6>=$E10,H$4<=$F10),1,"") | I10: =IF(AND($E10>0,$F10>0,I$4+6>=$E10,I$4<=$F10),1,"") | J10: =IF(AND($E10>0,$F10>0,J$4+6>=$E10,J$4<=$F10),1,"") | K10: =IF(AND($E10>0,$F10>0,K$4+6>=$E10,K$4<=$F10),1,"") | L10: =IF(AND($E10>0,$F10>0,L$4+6>=$E10,L$4<=$F10),1,"") | M10: =IF(AND($E10>0,$F10>0,M$4+6>=$E10,M$4<=$F10),1,"") | N10: =IF(AND($E10>0,$F10>0,N$4+6>=$E10,N$4<=$F10),1,"") | ... BF10: =IF(AND($E10>0,$F10>0,BF$4+6>=$E10,BF$4<=$F10),1,"")
